Workbook

Sheet موازنة دمياط
A1: موازنة مدرسة ابدأ الوطنية – دمياط | السنة المالية سبتمبر 2026 – أغسطس 2027 (ج.م)
A2: الخلايا الصفراء الفاتحة فقط للإدخال (البند، المخصص السنوي، مخصص كل شهر). «المنصرف» يُحسب تلقائيًا من ملف العهد والمصروفات (شيت «عهد ومصروفات دمياط» – المصروفات التي وافق عليها المدير المباشر). المتبقي/العجز = المخصص − المنصرف، والعجز يظهر بالأحمر. لإضافة بند جديد اكتبه في أول صف فارغ.
A3: المخصص السنوي | B3: إجمالي المنصرف | D3: المتبقي / العجز السنوي | G3: نسبة الصرف من الموازنة | J3: بنود بها عجز
A4: =SUM($B$8:$B$67) | B4: =SUM($AO$8:$AO$67) | D4: =SUM($B$8:$B$67)-SUM($AO$8:$AO$67) | G4: =IF(SUM($B$8:$B$67)=0,0,SUM($AO$8:$AO$67)/SUM($B$8:$B$67)) | J4: =COUNTIF($AS$8:$AS$67,1)
M5: ■ برتقالي في «إجمالي المخصص السنوي» = مجموع الأشهر لا يساوي المخصص السنوي (من الملف الأصلي) · ■ أحمر في اسم البند = يوجد عجز
D6: سبتمبر 2026 | G6: أكتوبر 2026 | J6: نوفمبر 2026 | M6: ديسمبر 2026 | P6: يناير 2027 | S6: فبراير 2027 | V6: مارس 2027 | Y6: أبريل 2027 | AB6: مايو 2027 | AE6: يونيو 2027 | AH6: يوليو 2027 | AK6: أغسطس 2027 | AN6: الإجمالي السنوي
A7: البند | B7: المخصص السنوي | C7: المخصص الشهري | D7: سبتمبر 2026 مخصص | E7: سبتمبر 2026 منصرف | F7: سبتمبر 2026 متبقي/عجز | G7: أكتوبر 2026 مخصص | H7: أكتوبر 2026 منصرف | I7: أكتوبر 2026 متبقي/عجز | J7: نوفمبر 2026 مخصص | K7: نوفمبر 2026 منصرف | L7: نوفمبر 2026 متبقي/عجز | M7: ديسمبر 2026 مخصص | N7: ديسمبر 2026 منصرف | O7: ديسمبر 2026 متبقي/عجز | P7: يناير 2027 مخصص | Q7: يناير 2027 منصرف | R7: يناير 2027 متبقي/عجز | S7: فبراير 2027 مخصص | T7: فبراير 2027 منصرف | U7: فبراير 2027 متبقي/عجز | V7: مارس 2027 مخصص | W7: مارس 2027 منصرف | X7: مارس 2027 متبقي/عجز | Y7: أبريل 2027 مخصص | Z7: أبريل 2027 منصرف | AA7: أبريل 2027 متبقي/عجز | AB7: مايو 2027 مخصص | AC7: مايو 2027 منصرف | AD7: مايو 2027 متبقي/عجز | AE7: يونيو 2027 مخصص | AF7: يونيو 2027 منصرف | AG7: يونيو 2027 متبقي/عجز | AH7: يوليو 2027 مخصص | AI7: يوليو 2027 منصرف | AJ7: يوليو 2027 متبقي/عجز | AK7: أغسطس 2027 مخصص | AL7: أغسطس 2027 منصرف | AM7: أغسطس 2027 متبقي/عجز | AN7: إجمالي المخصص السنوي | AO7: إجمالي المنصرف السنوي | AP7: المتبقي أو العجز السنوي | AQ7: def_months | AR7: overspend | AS7: def_flag | AT7: def_cum | AU7: top_key
A8: رواتب وحوافز | B8: 3618600 | C8: =IF(A8="","",N(B8)/12) | D8: 342057.5 | E8: =IF($A8="","",IFERROR(SUMPRODUCT(('[1]عهد ومصروفات دمياط'!$H$8:$H$5007=$A8)*('[1]عهد ومصروفات دمياط'!$S$8:$S$5007=1)*'[1]عهد ومصروفات دمياط'!$T$8:$T$5007),0)) | F8: =IF($A8="","",N(D8)-N(E8)) | G8: 342057.5 | H8: =IF($A8="","",IFERROR(SUMPRODUCT(('[1]عهد ومصروفات دمياط'!$H$8:$H$5007=$A8)*('[1]عهد ومصروفات دمياط'!$S$8:$S$5007=2)*'[1]عهد ومصروفات دمياط'!$T$8:$T$5007),0)) | I8: =IF($A8="","",N(G8)-N(H8)) | J8: 342057.5 | K8: =IF($A8="","",IFERROR(SUMPRODUCT(('[1]عهد ومصروفات دمياط'!$H$8:$H$5007=$A8)*('[1]عهد ومصروفات دمياط'!$S$8:$S$5007=3)*'[1]عهد ومصروفات دمياط'!$T$8:$T$5007),0)) | L8: =IF($A8="","",N(J8)-N(K8)) | M8: 342057.5 | N8: =IF($A8="","",IFERROR(SUMPRODUCT(('[1]عهد ومصروفات دمياط'!$H$8:$H$5007=$A8)*('[1]عهد ومصروفات دمياط'!$S$8:$S$5007=4)*'[1]عهد ومصروفات دمياط'!$T$8:$T$5007),0)) | O8: =IF($A8="","",N(M8)-N(N8)) | P8: 342057.5 | Q8: =IF($A8="","",IFERROR(SUMPRODUCT(('[1]عهد ومصروفات دمياط'!$H$8:$H$5007=$A8)*('[1]عهد ومصروفات دمياط'!$S$8:$S$5007=5)*'[1]عهد ومصروفات دمياط'!$T$8:$T$5007),0)) | R8: =IF($A8="","",N(P8)-N(Q8)) | S8: 342057.5 | T8: =IF($A8="","",IFERROR(SUMPRODUCT(('[1]عهد ومصروفات دمياط'!$H$8:$H$5007=$A8)*('[1]عهد ومصروفات دمياط'!$S$8:$S$5007=6)*'[1]عهد ومصروفات دمياط'!$T$8:$T$5007),0)) | U8: =IF($A8="","",N(S8)-N(T8)) | V8: 342057.5 | W8: =IF($A8="","",IFERROR(SUMPRODUCT(('[1]عهد ومصروفات دمياط'!$H$8:$H$5007=$A8)*('[1]عهد ومصروفات دمياط'!$S$8:$S$5007=7)*'[1]عهد ومصروفات دمياط'!$T$8:$T$5007),0)) | X8: =IF($A8="","",N(V8)-N(W8)) | Y8: 342057.5 | Z8: =IF($A8="","",IFERROR(SUMPRODUCT(('[1]عهد ومصروفات دمياط'!$H$8:$H$5007=$A8)*('[1]عهد ومصروفات دمياط'!$S$8:$S$5007=8)*'[1]عهد ومصروفات دمياط'!$T$8:$T$5007),0)) | AA8: =IF($A8="","",N(Y8)-N(Z8)) | AB8: 342057.5 | AC8: =IF($A8="","",IFERROR(SUMPRODUCT(('[1]عهد ومصروفات دمياط'!$H$8:$H$5007=$A8)*('[1]عهد ومصروفات دمياط'!$S$8:$S$5007=9)*'[1]عهد ومصروفات دمياط'!$T$8:$T$5007),0)) | AD8: =IF($A8="","",N(AB8)-N(AC8)) | AE8: 342057.5 | AF8: =IF($A8="","",IFERROR(SUMPRODUCT(('[1]عهد ومصروفات دمياط'!$H$8:$H$5007=$A8)*('[1]عهد ومصروفات دمياط'!$S$8:$S$5007=10)*'[1]عهد ومصروفات دمياط'!$T$8:$T$5007),0)) | AG8: =IF($A8="","",N(AE8)-N(AF8)) | AH8: 342057.5 | AI8: =IF($A8="","",IFERROR(SUMPRODUCT(('[1]عهد ومصروفات دمياط'!$H$8:$H$5007=$A8)*('[1]عهد ومصروفات دمياط'!$S$8:$S$5007=11)*'[1]عهد ومصروفات دمياط'!$T$8:$T$5007),0)) | AJ8: =IF($A8="","",N(AH8)-N(AI8)) | AK8: 342057.5 | AL8: =IF($A8="","",IFERROR(SUMPRODUCT(('[1]عهد ومصروفات دمياط'!$H$8:$H$5007=$A8)*('[1]عهد ومصروفات دمياط'!$S$8:$S$5007=12)*'[1]عهد ومصروفات دمياط'!$T$8:$T$5007),0)) | AM8: =IF($A8="","",N(AK8)-N(AL8)) | AN8: =IF(A8="","",N(D8)+N(G8)+N(J8)+N(M8)+N(P8)+N(S8)+N(V8)+N(Y8)+N(AB8)+N(AE8)+N(AH8)+N(AK8)) | AO8: =IF(A8="","",N(E8)+N(H8)+N(K8)+N(N8)+N(Q8)+N(T8)+N(W8)+N(Z8)+N(AC8)+N(AF8)+N(AI8)+N(AL8)) | AP8: =IF(A8="","",N(B8)-AO8) | AQ8: =IF(A8="",0,(N(F8)<0)+(N(I8)<0)+(N(L8)<0)+(N(O8)<0)+(N(R8)<0)+(N(U8)<0)+(N(X8)<0)+(N(AA8)<0)+(N(AD8)<0)+(N(AG8)<0)+(N(AJ8)<0)+(N(AM8)<0)) | AR8: =IF(A8="",0,MAX(0,-N(F8))+MAX(0,-N(I8))+MAX(0,-N(L8))+MAX(0,-N(O8))+MAX(0,-N(R8))+MAX(0,-N(U8))+MAX(0,-N(X8))+MAX(0,-N(AA8))+MAX(0,-N(AD8))+MAX(0,-N(AG8))+MAX(0,-N(AJ8))+MAX(0,-N(AM8))) | AS8: =IF(A8="",0,IF(OR(N(AP8)<0,AQ8>0),1,0)) | AT8: =AS8 | AU8: =IF(A8="",-1,N(AO8)+ROW()/10000000)
A9: تدريب المعلمين | B9: 114000 | C9: =IF(A9="","",N(B9)/12) | D9: 0 | E9: =IF($A9="","",IFERROR(SUMPRODUCT(('[1]عهد ومصروفات دمياط'!$H$8:$H$5007=$A9)*('[1]عهد ومصروفات دمياط'!$S$8:$S$5007=1)*'[1]عهد ومصروفات دمياط'!$T$8:$T$5007),0)) | F9: =IF($A9="","",N(D9)-N(E9)) | G9: 0 | H9: =IF($A9="","",IFERROR(SUMPRODUCT(('[1]عهد ومصروفات دمياط'!$H$8:$H$5007=$A9)*('[1]عهد ومصروفات دمياط'!$S$8:$S$5007=2)*'[1]عهد ومصروفات دمياط'!$T$8:$T$5007),0)) | I9: =IF($A9="","",N(G9)-N(H9)) | J9: 0 | K9: =IF($A9="","",IFERROR(SUMPRODUCT(('[1]عهد ومصروفات دمياط'!$H$8:$H$5007=$A9)*('[1]عهد ومصروفات دمياط'!$S$8:$S$5007=3)*'[1]عهد ومصروفات دمياط'!$T$8:$T$5007),0)) | L9: =IF($A9="","",N(J9)-N(K9)) | M9: 0 | N9: =IF($A9="","",IFERROR(SUMPRODUCT(('[1]عهد ومصروفات دمياط'!$H$8:$H$5007=$A9)*('[1]عهد ومصروفات دمياط'!$S$8:$S$5007=4)*'[1]عهد ومصروفات دمياط'!$T$8:$T$5007),0)) | O9: =IF($A9="","",N(M9)-N(N9)) | P9: 57000 | Q9: =IF($A9="","",IFERROR(SUMPRODUCT(('[1]عهد ومصروفات دمياط'!$H$8:$H$5007=$A9)*('[1]عهد ومصروفات دمياط'!$S$8:$S$5007=5)*'[1]عهد ومصروفات دمياط'!$T$8:$T$5007),0)) | R9: =IF($A9="","",N(P9)-N(Q9)) | S9: 0 | T9: =IF($A9="","",IFERROR(SUMPRODUCT(('[1]عهد ومصروفات دمياط'!$H$8:$H$5007=$A9)*('[1]عهد ومصروفات دمياط'!$S$8:$S$5007=6)*'[1]عهد ومصروفات دمياط'!$T$8:$T$5007),0)) | U9: =IF($A9="","",N(S9)-N(T9)) | V9: 0 | W9: =IF($A9="","",IFERROR(SUMPRODUCT(('[1]عهد ومصروفات دمياط'!$H$8:$H$5007=$A9)*('[1]عهد ومصروفات دمياط'!$S$8:$S$5007=7)*'[1]عهد ومصروفات دمياط'!$T$8:$T$5007),0)) | X9: =IF($A9="","",N(V9)-N(W9)) | Y9: 0 | Z9: =IF($A9="","",IFERROR(SUMPRODUCT(('[1]عهد ومصروفات دمياط'!$H$8:$H$5007=$A9)*('[1]عهد ومصروفات دمياط'!$S$8:$S$5007=8)*'[1]عهد ومصروفات دمياط'!$T$8:$T$5007),0)) | AA9: =IF($A9="","",N(Y9)-N(Z9)) | AB9: 0 | AC9: =IF($A9="","",IFERROR(SUMPRODUCT(('[1]عهد ومصروفات دمياط'!$H$8:$H$5007=$A9)*('[1]عهد ومصروفات دمياط'!$S$8:$S$5007=9)*'[1]عهد ومصروفات دمياط'!$T$8:$T$5007),0)) | AD9: =IF($A9="","",N(AB9)-N(AC9)) | AE9: 0 | AF9: =IF($A9="","",IFERROR(SUMPRODUCT(('[1]عهد ومصروفات دمياط'!$H$8:$H$5007=$A9)*('[1]عهد ومصروفات دمياط'!$S$8:$S$5007=10)*'[1]عهد ومصروفات دمياط'!$T$8:$T$5007),0)) | AG9: =IF($A9="","",N(AE9)-N(AF9)) | AH9: 0 | AI9: =IF($A9="","",IFERROR(SUMPRODUCT(('[1]عهد ومصروفات دمياط'!$H$8:$H$5007=$A9)*('[1]عهد ومصروفات دمياط'!$S$8:$S$5007=11)*'[1]عهد ومصروفات دمياط'!$T$8:$T$5007),0)) | AJ9: =IF($A9="","",N(AH9)-N(AI9)) | AK9: 57000 | AL9: =IF($A9="","",IFERROR(SUMPRODUCT(('[1]عهد ومصروفات دمياط'!$H$8:$H$5007=$A9)*('[1]عهد ومصروفات دمياط'!$S$8:$S$5007=12)*'[1]عهد ومصروفات دمياط'!$T$8:$T$5007),0)) | AM9: =IF($A9="","",N(AK9)-N(AL9)) | AN9: =IF(A9="","",N(D9)+N(G9)+N(J9)+N(M9)+N(P9)+N(S9)+N(V9)+N(Y9)+N(AB9)+N(AE9)+N(AH9)+N(AK9)) | AO9: =IF(A9="","",N(E9)+N(H9)+N(K9)+N(N9)+N(Q9)+N(T9)+N(W9)+N(Z9)+N(AC9)+N(AF9)+N(AI9)+N(AL9)) | AP9: =IF(A9="","",N(B9)-AO9) | AQ9: =IF(A9="",0,(N(F9)<0)+(N(I9)<0)+(N(L9)<0)+(N(O9)<0)+(N(R9)<0)+(N(U9)<0)+(N(X9)<0)+(N(AA9)<0)+(N(AD9)<0)+(N(AG9)<0)+(N(AJ9)<0)+(N(AM9)<0)) | AR9: =IF(A9="",0,MAX(0,-N(F9))+MAX(0,-N(I9))+MAX(0,-N(L9))+MAX(0,-N(O9))+MAX(0,-N(R9))+MAX(0,-N(U9))+MAX(0,-N(X9))+MAX(0,-N(AA9))+MAX(0,-N(AD9))+MAX(0,-N(AG9))+MAX(0,-N(AJ9))+MAX(0,-N(AM9))) | AS9: =IF(A9="",0,IF(OR(N(AP9)<0,AQ9>0),1,0)) | AT9: =AT8+AS9 | AU9: =IF(A9="",-1,N(AO9)+ROW()/10000000)
A10: انتقالات وبدلات المتابعة الميدانية | B10: 72000 | C10: =IF(A10="","",N(B10)/12) | D10: 9000 | E10: =IF($A10="","",IFERROR(SUMPRODUCT(('[1]عهد ومصروفات دمياط'!$H$8:$H$5007=$A10)*('[1]عهد ومصروفات دمياط'!$S$8:$S$5007=1)*'[1]عهد ومصروفات دمياط'!$T$8:$T$5007),0)) | F10: =IF($A10="","",N(D10)-N(E10)) | G10: 9000 | H10: =IF($A10="","",IFERROR(SUMPRODUCT(('[1]عهد ومصروفات دمياط'!$H$8:$H$5007=$A10)*('[1]عهد ومصروفات دمياط'!$S$8:$S$5007=2)*'[1]عهد ومصروفات دمياط'!$T$8:$T$5007),0)) | I10: =IF($A10="","",N(G10)-N(H10)) | J10: 9000 | K10: =IF($A10="","",IFERROR(SUMPRODUCT(('[1]عهد ومصروفات دمياط'!$H$8:$H$5007=$A10)*('[1]عهد ومصروفات دمياط'!$S$8:$S$5007=3)*'[1]عهد ومصروفات دمياط'!$T$8:$T$5007),0)) | L10: =IF($A10="","",N(J10)-N(K10)) | M10: 9000 | N10: =IF($A10="","",IFERROR(SUMPRODUCT(('[1]عهد ومصروفات دمياط'!$H$8:$H$5007=$A10)*('[1]عهد ومصروفات دمياط'!$S$8:$S$5007=4)*'[1]عهد ومصروفات دمياط'!$T$8:$T$5007),0)) | O10: =IF($A10="","",N(M10)-N(N10)) | P10: 9000 | Q10: =IF($A10="","",IFERROR(SUMPRODUCT(('[1]عهد ومصروفات دمياط'!$H$8:$H$5007=$A10)*('[1]عهد ومصروفات دمياط'!$S$8:$S$5007=5)*'[1]عهد ومصروفات دمياط'!$T$8:$T$5007),0)) | R10: =IF($A10="","",N(P10)-N(Q10)) | S10: 9000 | T10: =IF($A10="","",IFERROR(SUMPRODUCT(('[1]عهد ومصروفات دمياط'!$H$8:$H$5007=$A10)*('[1]عهد ومصروفات دمياط'!$S$8:$S$5007=6)*'[1]عهد ومصروفات دمياط'!$T$8:$T$5007),0)) | U10: =IF($A10="","",N(S10)-N(T10)) | V10: 9000 | W10: =IF($A10="","",IFERROR(SUMPRODUCT(('[1]عهد ومصروفات دمياط'!$H$8:$H$5007=$A10)*('[1]عهد ومصروفات دمياط'!$S$8:$S$5007=7)*'[1]عهد ومصروفات دمياط'!$T$8:$T$5007),0)) | X10: =IF($A10="","",N(V10)-N(W10)) | Y10: 9000 | Z10: =IF($A10="","",IFERROR(SUMPRODUCT(('[1]عهد ومصروفات دمياط'!$H$8:$H$5007=$A10)*('[1]عهد ومصروفات دمياط'!$S$8:$S$5007=8)*'[1]عهد ومصروفات دمياط'!$T$8:$T$5007),0)) | AA10: =IF($A10="","",N(Y10)-N(Z10)) | AB10: 0 | AC10: =IF($A10="","",IFERROR(SUMPRODUCT(('[1]عهد ومصروفات دمياط'!$H$8:$H$5007=$A10)*('[1]عهد ومصروفات دمياط'!$S$8:$S$5007=9)*'[1]عهد ومصروفات دمياط'!$T$8:$T$5007),0)) | AD10: =IF($A10="","",N(AB10)-N(AC10)) | AE10: 0 | AF10: =IF($A10="","",IFERROR(SUMPRODUCT(('[1]عهد ومصروفات دمياط'!$H$8:$H$5007=$A10)*('[1]عهد ومصروفات دمياط'!$S$8:$S$5007=10)*'[1]عهد ومصروفات دمياط'!$T$8:$T$5007),0)) | AG10: =IF($A10="","",N(AE10)-N(AF10)) | AH10: 0 | AI10: =IF($A10="","",IFERROR(SUMPRODUCT(('[1]عهد ومصروفات دمياط'!$H$8:$H$5007=$A10)*('[1]عهد ومصروفات دمياط'!$S$8:$S$5007=11)*'[1]عهد ومصروفات دمياط'!$T$8:$T$5007),0)) | AJ10: =IF($A10="","",N(AH10)-N(AI10)) | AK10: 0 | AL10: =IF($A10="","",IFERROR(SUMPRODUCT(('[1]عهد ومصروفات دمياط'!$H$8:$H$5007=$A10)*('[1]عهد ومصروفات دمياط'!$S$8:$S$5007=12)*'[1]عهد ومصروفات دمياط'!$T$8:$T$5007),0)) | AM10: =IF($A10="","",N(AK10)-N(AL10)) | AN10: =IF(A10="","",N(D10)+N(G10)+N(J10)+N(M10)+N(P10)+N(S10)+N(V10)+N(Y10)+N(AB10)+N(AE10)+N(AH10)+N(AK10)) | AO10: =IF(A10="","",N(E10)+N(H10)+N(K10)+N(N10)+N(Q10)+N(T10)+N(W10)+N(Z10)+N(AC10)+N(AF10)+N(AI10)+N(AL10)) | AP10: =IF(A10="","",N(B10)-AO10) | AQ10: =IF(A10="",0,(N(F10)<0)+(N(I10)<0)+(N(L10)<0)+(N(O10)<0)+(N(R10)<0)+(N(U10)<0)+(N(X10)<0)+(N(AA10)<0)+(N(AD10)<0)+(N(AG10)<0)+(N(AJ10)<0)+(N(AM10)<0)) | AR10: =IF(A10="",0,MAX(0,-N(F10))+MAX(0,-N(I10))+MAX(0,-N(L10))+MAX(0,-N(O10))+MAX(0,-N(R10))+MAX(0,-N(U10))+MAX(0,-N(X10))+MAX(0,-N(AA10))+MAX(0,-N(AD10))+MAX(0,-N(AG10))+MAX(0,-N(AJ10))+MAX(0,-N(AM10))) | AS10: =IF(A10="",0,IF(OR(N(AP10)<0,AQ10>0),1,0)) | AT10: =AT9+AS10 | AU10: =IF(A10="",-1,N(AO10)+ROW()/10000000)
A11: معدات الأمن والسلامة (الصف الأول) | B11: 62500 | C11: =IF(A11="","",N(B11)/12) | D11: 62500 | E11: =IF($A11="","",IFERROR(SUMPRODUCT(('[1]عهد ومصروفات دمياط'!$H$8:$H$5007=$A11)*('[1]عهد ومصروفات دمياط'!$S$8:$S$5007=1)*'[1]عهد ومصروفات دمياط'!$T$8:$T$5007),0)) | F11: =IF($A11="","",N(D11)-N(E11)) | G11: 0 | H11: =IF($A11="","",IFERROR(SUMPRODUCT(('[1]عهد ومصروفات دمياط'!$H$8:$H$5007=$A11)*('[1]عهد ومصروفات دمياط'!$S$8:$S$5007=2)*'[1]عهد ومصروفات دمياط'!$T$8:$T$5007),0)) | I11: =IF($A11="","",N(G11)-N(H11)) | J11: 0 | K11: =IF($A11="","",IFERROR(SUMPRODUCT(('[1]عهد ومصروفات دمياط'!$H$8:$H$5007=$A11)*('[1]عهد ومصروفات دمياط'!$S$8:$S$5007=3)*'[1]عهد ومصروفات دمياط'!$T$8:$T$5007),0)) | L11: =IF($A11="","",N(J11)-N(K11)) | M11: 0 | N11: =IF($A11="","",IFERROR(SUMPRODUCT(('[1]عهد ومصروفات دمياط'!$H$8:$H$5007=$A11)*('[1]عهد ومصروفات دمياط'!$S$8:$S$5007=4)*'[1]عهد ومصروفات دمياط'!$T$8:$T$5007),0)) | O11: =IF($A11="","",N(M11)-N(N11)) | P11: 0 | Q11: =IF($A11="","",IFERROR(SUMPRODUCT(('[1]عهد ومصروفات دمياط'!$H$8:$H$5007=$A11)*('[1]عهد ومصروفات دمياط'!$S$8:$S$5007=5)*'[1]عهد ومصروفات دمياط'!$T$8:$T$5007),0)) | R11: =IF($A11="","",N(P11)-N(Q11)) | S11: 0 | T11: =IF($A11="","",IFERROR(SUMPRODUCT(('[1]عهد ومصروفات دمياط'!$H$8:$H$5007=$A11)*('[1]عهد ومصروفات دمياط'!$S$8:$S$5007=6)*'[1]عهد ومصروفات دمياط'!$T$8:$T$5007),0)) | U11: =IF($A11="","",N(S11)-N(T11)) | V11: 0 | W11: =IF($A11="","",IFERROR(SUMPRODUCT(('[1]عهد ومصروفات دمياط'!$H$8:$H$5007=$A11)*('[1]عهد ومصروفات دمياط'!$S$8:$S$5007=7)*'[1]عهد ومصروفات دمياط'!$T$8:$T$5007),0)) | X11: =IF($A11="","",N(V11)-N(W11)) | Y11: 0 | Z11: =IF($A11="","",IFERROR(SUMPRODUCT(('[1]عهد ومصروفات دمياط'!$H$8:$H$5007=$A11)*('[1]عهد ومصروفات دمياط'!$S$8:$S$5007=8)*'[1]عهد ومصروفات دمياط'!$T$8:$T$5007),0)) | AA11: =IF($A11="","",N(Y11)-N(Z11)) | AB11: 0 | AC11: =IF($A11="","",IFERROR(SUMPRODUCT(('[1]عهد ومصروفات دمياط'!$H$8:$H$5007=$A11)*('[1]عهد ومصروفات دمياط'!$S$8:$S$5007=9)*'[1]عهد ومصروفات دمياط'!$T$8:$T$5007),0)) | AD11: =IF($A11="","",N(AB11)-N(AC11)) | AE11: 0 | AF11: =IF($A11="","",IFERROR(SUMPRODUCT(('[1]عهد ومصروفات دمياط'!$H$8:$H$5007=$A11)*('[1]عهد ومصروفات دمياط'!$S$8:$S$5007=10)*'[1]عهد ومصروفات دمياط'!$T$8:$T$5007),0)) | AG11: =IF($A11="","",N(AE11)-N(AF11)) | AH11: 0 | AI11: =IF($A11="","",IFERROR(SUMPRODUCT(('[1]عهد ومصروفات دمياط'!$H$8:$H$5007=$A11)*('[1]عهد ومصروفات دمياط'!$S$8:$S$5007=11)*'[1]عهد ومصروفات دمياط'!$T$8:$T$5007),0)) | AJ11: =IF($A11="","",N(AH11)-N(AI11)) | AK11: 0 | AL11: =IF($A11="","",IFERROR(SUMPRODUCT(('[1]عهد ومصروفات دمياط'!$H$8:$H$5007=$A11)*('[1]عهد ومصروفات دمياط'!$S$8:$S$5007=12)*'[1]عهد ومصروفات دمياط'!$T$8:$T$5007),0)) | AM11: =IF($A11="","",N(AK11)-N(AL11)) | AN11: =IF(A11="","",N(D11)+N(G11)+N(J11)+N(M11)+N(P11)+N(S11)+N(V11)+N(Y11)+N(AB11)+N(AE11)+N(AH11)+N(AK11)) | AO11: =IF(A11="","",N(E11)+N(H11)+N(K11)+N(N11)+N(Q11)+N(T11)+N(W11)+N(Z11)+N(AC11)+N(AF11)+N(AI11)+N(AL11)) | AP11: =IF(A11="","",N(B11)-AO11) | AQ11: =IF(A11="",0,(N(F11)<0)+(N(I11)<0)+(N(L11)<0)+(N(O11)<0)+(N(R11)<0)+(N(U11)<0)+(N(X11)<0)+(N(AA11)<0)+(N(AD11)<0)+(N(AG11)<0)+(N(AJ11)<0)+(N(AM11)<0)) | AR11: =IF(A11="",0,MAX(0,-N(F11))+MAX(0,-N(I11))+MAX(0,-N(L11))+MAX(0,-N(O11))+MAX(0,-N(R11))+MAX(0,-N(U11))+MAX(0,-N(X11))+MAX(0,-N(AA11))+MAX(0,-N(AD11))+MAX(0,-N(AG11))+MAX(0,-N(AJ11))+MAX(0,-N(AM11))) | AS11: =IF(A11="",0,IF(OR(N(AP11)<0,AQ11>0),1,0)) | AT11: =AT10+AS11 | AU11: =IF(A11="",-1,N(AO11)+ROW()/10000000)
A12: الزى المدرسى (الصف الأول) | B12: 181750 | C12: =IF(A12="","",N(B12)/12) | D12: 181750 | E12: =IF($A12="","",IFERROR(SUMPRODUCT(('[1]عهد ومصروفات دمياط'!$H$8:$H$5007=$A12)*('[1]عهد ومصروفات دمياط'!$S$8:$S$5007=1)*'[1]عهد ومصروفات دمياط'!$T$8:$T$5007),0)) | F12: =IF($A12="","",N(D12)-N(E12)) | G12: 0 | H12: =IF($A12="","",IFERROR(SUMPRODUCT(('[1]عهد ومصروفات دمياط'!$H$8:$H$5007=$A12)*('[1]عهد ومصروفات دمياط'!$S$8:$S$5007=2)*'[1]عهد ومصروفات دمياط'!$T$8:$T$5007),0)) | I12: =IF($A12="","",N(G12)-N(H12)) | J12: 0 | K12: =IF($A12="","",IFERROR(SUMPRODUCT(('[1]عهد ومصروفات دمياط'!$H$8:$H$5007=$A12)*('[1]عهد ومصروفات دمياط'!$S$8:$S$5007=3)*'[1]عهد ومصروفات دمياط'!$T$8:$T$5007),0)) | L12: =IF($A12="","",N(J12)-N(K12)) | M12: 0 | N12: =IF($A12="","",IFERROR(SUMPRODUCT(('[1]عهد ومصروفات دمياط'!$H$8:$H$5007=$A12)*('[1]عهد ومصروفات دمياط'!$S$8:$S$5007=4)*'[1]عهد ومصروفات دمياط'!$T$8:$T$5007),0)) | O12: =IF($A12="","",N(M12)-N(N12)) | P12: 0 | Q12: =IF($A12="","",IFERROR(SUMPRODUCT(('[1]عهد ومصروفات دمياط'!$H$8:$H$5007=$A12)*('[1]عهد ومصروفات دمياط'!$S$8:$S$5007=5)*'[1]عهد ومصروفات دمياط'!$T$8:$T$5007),0)) | R12: =IF($A12="","",N(P12)-N(Q12)) | S12: 0 | T12: =IF($A12="","",IFERROR(SUMPRODUCT(('[1]عهد ومصروفات دمياط'!$H$8:$H$5007=$A12)*('[1]عهد ومصروفات دمياط'!$S$8:$S$5007=6)*'[1]عهد ومصروفات دمياط'!$T$8:$T$5007),0)) | U12: =IF($A12="","",N(S12)-N(T12)) | V12: 0 | W12: =IF($A12="","",IFERROR(SUMPRODUCT(('[1]عهد ومصروفات دمياط'!$H$8:$H$5007=$A12)*('[1]عهد ومصروفات دمياط'!$S$8:$S$5007=7)*'[1]عهد ومصروفات دمياط'!$T$8:$T$5007),0)) | X12: =IF($A12="","",N(V12)-N(W12)) | Y12: 0 | Z12: =IF($A12="","",IFERROR(SUMPRODUCT(('[1]عهد ومصروفات دمياط'!$H$8:$H$5007=$A12)*('[1]عهد ومصروفات دمياط'!$S$8:$S$5007=8)*'[1]عهد ومصروفات دمياط'!$T$8:$T$5007),0)) | AA12: =IF($A12="","",N(Y12)-N(Z12)) | AB12: 0 | AC12: =IF($A12="","",IFERROR(SUMPRODUCT(('[1]عهد ومصروفات دمياط'!$H$8:$H$5007=$A12)*('[1]عهد ومصروفات دمياط'!$S$8:$S$5007=9)*'[1]عهد ومصروفات دمياط'!$T$8:$T$5007),0)) | AD12: =IF($A12="","",N(AB12)-N(AC12)) | AE12: 0 | AF12: =IF($A12="","",IFERROR(SUMPRODUCT(('[1]عهد ومصروفات دمياط'!$H$8:$H$5007=$A12)*('[1]عهد ومصروفات دمياط'!$S$8:$S$5007=10)*'[1]عهد ومصروفات دمياط'!$T$8:$T$5007),0)) | AG12: =IF($A12="","",N(AE12)-N(AF12)) | AH12: 0 | AI12: =IF($A12="","",IFERROR(SUMPRODUCT(('[1]عهد ومصروفات دمياط'!$H$8:$H$5007=$A12)*('[1]عهد ومصروفات دمياط'!$S$8:$S$5007=11)*'[1]عهد ومصروفات دمياط'!$T$8:$T$5007),0)) | AJ12: =IF($A12="","",N(AH12)-N(AI12)) | AK12: 0 | AL12: =IF($A12="","",IFERROR(SUMPRODUCT(('[1]عهد ومصروفات دمياط'!$H$8:$H$5007=$A12)*('[1]عهد ومصروفات دمياط'!$S$8:$S$5007=12)*'[1]عهد ومصروفات دمياط'!$T$8:$T$5007),0)) | AM12: =IF($A12="","",N(AK12)-N(AL12)) | AN12: =IF(A12="","",N(D12)+N(G12)+N(J12)+N(M12)+N(P12)+N(S12)+N(V12)+N(Y12)+N(AB12)+N(AE12)+N(AH12)+N(AK12)) | AO12: =IF(A12="","",N(E12)+N(H12)+N(K12)+N(N12)+N(Q12)+N(T12)+N(W12)+N(Z12)+N(AC12)+N(AF12)+N(AI12)+N(AL12)) | AP12: =IF(A12="","",N(B12)-AO12) | AQ12: =IF(A12="",0,(N(F12)<0)+(N(I12)<0)+(N(L12)<0)+(N(O12)<0)+(N(R12)<0)+(N(U12)<0)+(N(X12)<0)+(N(AA12)<0)+(N(AD12)<0)+(N(AG12)<0)+(N(AJ12)<0)+(N(AM12)<0)) | AR12: =IF(A12="",0,MAX(0,-N(F12))+MAX(0,-N(I12))+MAX(0,-N(L12))+MAX(0,-N(O12))+MAX(0,-N(R12))+MAX(0,-N(U12))+MAX(0,-N(X12))+MAX(0,-N(AA12))+MAX(0,-N(AD12))+MAX(0,-N(AG12))+MAX(0,-N(AJ12))+MAX(0,-N(AM12))) | AS12: =IF(A12="",0,IF(OR(N(AP12)<0,AQ12>0),1,0)) | AT12: =AT11+AS12 | AU12: =IF(A12="",-1,N(AO12)+ROW()/10000000)
A13: انتقالات الموقع – الصف الثالث | B13: 135000 | C13: =IF(A13="","",N(B13)/12) | D13: 0 | E13: =IF($A13="","",IFERROR(SUMPRODUCT(('[1]عهد ومصروفات دمياط'!$H$8:$H$5007=$A13)*('[1]عهد ومصروفات دمياط'!$S$8:$S$5007=1)*'[1]عهد ومصروفات دمياط'!$T$8:$T$5007),0)) | F13: =IF($A13="","",N(D13)-N(E13)) | G13: 0 | H13: =IF($A13="","",IFERROR(SUMPRODUCT(('[1]عهد ومصروفات دمياط'!$H$8:$H$5007=$A13)*('[1]عهد ومصروفات دمياط'!$S$8:$S$5007=2)*'[1]عهد ومصروفات دمياط'!$T$8:$T$5007),0)) | I13: =IF($A13="","",N(G13)-N(H13)) | J13: 22500 | K13: =IF($A13="","",IFERROR(SUMPRODUCT(('[1]عهد ومصروفات دمياط'!$H$8:$H$5007=$A13)*('[1]عهد ومصروفات دمياط'!$S$8:$S$5007=3)*'[1]عهد ومصروفات دمياط'!$T$8:$T$5007),0)) | L13: =IF($A13="","",N(J13)-N(K13)) | M13: 45000 | N13: =IF($A13="","",IFERROR(SUMPRODUCT(('[1]عهد ومصروفات دمياط'!$H$8:$H$5007=$A13)*('[1]عهد ومصروفات دمياط'!$S$8:$S$5007=4)*'[1]عهد ومصروفات دمياط'!$T$8:$T$5007),0)) | O13: =IF($A13="","",N(M13)-N(N13)) | P13: 0 | Q13: =IF($A13="","",IFERROR(SUMPRODUCT(('[1]عهد ومصروفات دمياط'!$H$8:$H$5007=$A13)*('[1]عهد ومصروفات دمياط'!$S$8:$S$5007=5)*'[1]عهد ومصروفات دمياط'!$T$8:$T$5007),0)) | R13: =IF($A13="","",N(P13)-N(Q13)) | S13: 22500 | T13: =IF($A13="","",IFERROR(SUMPRODUCT(('[1]عهد ومصروفات دمياط'!$H$8:$H$5007=$A13)*('[1]عهد ومصروفات دمياط'!$S$8:$S$5007=6)*'[1]عهد ومصروفات دمياط'!$T$8:$T$5007),0)) | U13: =IF($A13="","",N(S13)-N(T13)) | V13: 45000 | W13: =IF($A13="","",IFERROR(SUMPRODUCT(('[1]عهد ومصروفات دمياط'!$H$8:$H$5007=$A13)*('[1]عهد ومصروفات دمياط'!$S$8:$S$5007=7)*'[1]عهد ومصروفات دمياط'!$T$8:$T$5007),0)) | X13: =IF($A13="","",N(V13)-N(W13)) | Y13: 0 | Z13: =IF($A13="","",IFERROR(SUMPRODUCT(('[1]عهد ومصروفات دمياط'!$H$8:$H$5007=$A13)*('[1]عهد ومصروفات دمياط'!$S$8:$S$5007=8)*'[1]عهد ومصروفات دمياط'!$T$8:$T$5007),0)) | AA13: =IF($A13="","",N(Y13)-N(Z13)) | AB13: 0 | AC13: =IF($A13="","",IFERROR(SUMPRODUCT(('[1]عهد ومصروفات دمياط'!$H$8:$H$5007=$A13)*('[1]عهد ومصروفات دمياط'!$S$8:$S$5007=9)*'[1]عهد ومصروفات دمياط'!$T$8:$T$5007),0)) | AD13: =IF($A13="","",N(AB13)-N(AC13)) | AE13: 0 | AF13: =IF($A13="","",IFERROR(SUMPRODUCT(('[1]عهد ومصروفات دمياط'!$H$8:$H$5007=$A13)*('[1]عهد ومصروفات دمياط'!$S$8:$S$5007=10)*'[1]عهد ومصروفات دمياط'!$T$8:$T$5007),0)) | AG13: =IF($A13="","",N(AE13)-N(AF13)) | AH13: 0 | AI13: =IF($A13="","",IFERROR(SUMPRODUCT(('[1]عهد ومصروفات دمياط'!$H$8:$H$5007=$A13)*('[1]عهد ومصروفات دمياط'!$S$8:$S$5007=11)*'[1]عهد ومصروفات دمياط'!$T$8:$T$5007),0)) | AJ13: =IF($A13="","",N(AH13)-N(AI13)) | AK13: 0 | AL13: =IF($A13="","",IFERROR(SUMPRODUCT(('[1]عهد ومصروفات دمياط'!$H$8:$H$5007=$A13)*('[1]عهد ومصروفات دمياط'!$S$8:$S$5007=12)*'[1]عهد ومصروفات دمياط'!$T$8:$T$5007),0)) | AM13: =IF($A13="","",N(AK13)-N(AL13)) | AN13: =IF(A13="","",N(D13)+N(G13)+N(J13)+N(M13)+N(P13)+N(S13)+N(V13)+N(Y13)+N(AB13)+N(AE13)+N(AH13)+N(AK13)) | AO13: =IF(A13="","",N(E13)+N(H13)+N(K13)+N(N13)+N(Q13)+N(T13)+N(W13)+N(Z13)+N(AC13)+N(AF13)+N(AI13)+N(AL13)) | AP13: =IF(A13="","",N(B13)-AO13) | AQ13: =IF(A13="",0,(N(F13)<0)+(N(I13)<0)+(N(L13)<0)+(N(O13)<0)+(N(R13)<0)+(N(U13)<0)+(N(X13)<0)+(N(AA13)<0)+(N(AD13)<0)+(N(AG13)<0)+(N(AJ13)<0)+(N(AM13)<0)) | AR13: =IF(A13="",0,MAX(0,-N(F13))+MAX(0,-N(I13))+MAX(0,-N(L13))+MAX(0,-N(O13))+MAX(0,-N(R13))+MAX(0,-N(U13))+MAX(0,-N(X13))+MAX(0,-N(AA13))+MAX(0,-N(AD13))+MAX(0,-N(AG13))+MAX(0,-N(AJ13))+MAX(0,-N(AM13))) | AS13: =IF(A13="",0,IF(OR(N(AP13)<0,AQ13>0),1,0)) | AT13: =AT12+AS13 | AU13: =IF(A13="",-1,N(AO13)+ROW()/10000000)
A14: وجبات الموقع – الصف الثالث | B14: 81675 | C14: =IF(A14="","",N(B14)/12) | D14: 0 | E14: =IF($A14="","",IFERROR(SUMPRODUCT(('[1]عهد ومصروفات دمياط'!$H$8:$H$5007=$A14)*('[1]عهد ومصروفات دمياط'!$S$8:$S$5007=1)*'[1]عهد ومصروفات دمياط'!$T$8:$T$5007),0)) | F14: =IF($A14="","",N(D14)-N(E14)) | G14: 0 | H14: =IF($A14="","",IFERROR(SUMPRODUCT(('[1]عهد ومصروفات دمياط'!$H$8:$H$5007=$A14)*('[1]عهد ومصروفات دمياط'!$S$8:$S$5007=2)*'[1]عهد ومصروفات دمياط'!$T$8:$T$5007),0)) | I14: =IF($A14="","",N(G14)-N(H14)) | J14: 13612.5 | K14: =IF($A14="","",IFERROR(SUMPRODUCT(('[1]عهد ومصروفات دمياط'!$H$8:$H$5007=$A14)*('[1]عهد ومصروفات دمياط'!$S$8:$S$5007=3)*'[1]عهد ومصروفات دمياط'!$T$8:$T$5007),0)) | L14: =IF($A14="","",N(J14)-N(K14)) | M14: 27225 | N14: =IF($A14="","",IFERROR(SUMPRODUCT(('[1]عهد ومصروفات دمياط'!$H$8:$H$5007=$A14)*('[1]عهد ومصروفات دمياط'!$S$8:$S$5007=4)*'[1]عهد ومصروفات دمياط'!$T$8:$T$5007),0)) | O14: =IF($A14="","",N(M14)-N(N14)) | P14: 0 | Q14: =IF($A14="","",IFERROR(SUMPRODUCT(('[1]عهد ومصروفات دمياط'!$H$8:$H$5007=$A14)*('[1]عهد ومصروفات دمياط'!$S$8:$S$5007=5)*'[1]عهد ومصروفات دمياط'!$T$8:$T$5007),0)) | R14: =IF($A14="","",N(P14)-N(Q14)) | S14: 13612.5 | T14: =IF($A14="","",IFERROR(SUMPRODUCT(('[1]عهد ومصروفات دمياط'!$H$8:$H$5007=$A14)*('[1]عهد ومصروفات دمياط'!$S$8:$S$5007=6)*'[1]عهد ومصروفات دمياط'!$T$8:$T$5007),0)) | U14: =IF($A14="","",N(S14)-N(T14)) | V14: 27225 | W14: =IF($A14="","",IFERROR(SUMPRODUCT(('[1]عهد ومصروفات دمياط'!$H$8:$H$5007=$A14)*('[1]عهد ومصروفات دمياط'!$S$8:$S$5007=7)*'[1]عهد ومصروفات دمياط'!$T$8:$T$5007),0)) | X14: =IF($A14="","",N(V14)-N(W14)) | Y14: 0 | Z14: =IF($A14="","",IFERROR(SUMPRODUCT(('[1]عهد ومصروفات دمياط'!$H$8:$H$5007=$A14)*('[1]عهد ومصروفات دمياط'!$S$8:$S$5007=8)*'[1]عهد ومصروفات دمياط'!$T$8:$T$5007),0)) | AA14: =IF($A14="","",N(Y14)-N(Z14)) | AB14: 0 | AC14: =IF($A14="","",IFERROR(SUMPRODUCT(('[1]عهد ومصروفات دمياط'!$H$8:$H$5007=$A14)*('[1]عهد ومصروفات دمياط'!$S$8:$S$5007=9)*'[1]عهد ومصروفات دمياط'!$T$8:$T$5007),0)) | AD14: =IF($A14="","",N(AB14)-N(AC14)) | AE14: 0 | AF14: =IF($A14="","",IFERROR(SUMPRODUCT(('[1]عهد ومصروفات دمياط'!$H$8:$H$5007=$A14)*('[1]عهد ومصروفات دمياط'!$S$8:$S$5007=10)*'[1]عهد ومصروفات دمياط'!$T$8:$T$5007),0)) | AG14: =IF($A14="","",N(AE14)-N(AF14)) | AH14: 0 | AI14: =IF($A14="","",IFERROR(SUMPRODUCT(('[1]عهد ومصروفات دمياط'!$H$8:$H$5007=$A14)*('[1]عهد ومصروفات دمياط'!$S$8:$S$5007=11)*'[1]عهد ومصروفات دمياط'!$T$8:$T$5007),0)) | AJ14: =IF($A14="","",N(AH14)-N(AI14)) | AK14: 0 | AL14: =IF($A14="","",IFERROR(SUMPRODUCT(('[1]عهد ومصروفات دمياط'!$H$8:$H$5007=$A14)*('[1]عهد ومصروفات دمياط'!$S$8:$S$5007=12)*'[1]عهد ومصروفات دمياط'!$T$8:$T$5007),0)) | AM14: =IF($A14="","",N(AK14)-N(AL14)) | AN14: =IF(A14="","",N(D14)+N(G14)+N(J14)+N(M14)+N(P14)+N(S14)+N(V14)+N(Y14)+N(AB14)+N(AE14)+N(AH14)+N(AK14)) | AO14: =IF(A14="","",N(E14)+N(H14)+N(K14)+N(N14)+N(Q14)+N(T14)+N(W14)+N(Z14)+N(AC14)+N(AF14)+N(AI14)+N(AL14)) | AP14: =IF(A14="","",N(B14)-AO14) | AQ14: =IF(A14="",0,(N(F14)<0)+(N(I14)<0)+(N(L14)<0)+(N(O14)<0)+(N(R14)<0)+(N(U14)<0)+(N(X14)<0)+(N(AA14)<0)+(N(AD14)<0)+(N(AG14)<0)+(N(AJ14)<0)+(N(AM14)<0)) | AR14: =IF(A14="",0,MAX(0,-N(F14))+MAX(0,-N(I14))+MAX(0,-N(L14))+MAX(0,-N(O14))+MAX(0,-N(R14))+MAX(0,-N(U14))+MAX(0,-N(X14))+MAX(0,-N(AA14))+MAX(0,-N(AD14))+MAX(0,-N(AG14))+MAX(0,-N(AJ14))+MAX(0,-N(AM14))) | AS14: =IF(A14="",0,IF(OR(N(AP14)<0,AQ14>0),1,0)) | AT14: =AT13+AS14 | AU14: =IF(A14="",-1,N(AO14)+ROW()/10000000)
A15: انتقالات الموقع – الصف الأول | B15: 90000 | C15: =IF(A15="","",N(B15)/12) | D15: 0 | E15: =IF($A15="","",IFERROR(SUMPRODUCT(('[1]عهد ومصروفات دمياط'!$H$8:$H$5007=$A15)*('[1]عهد ومصروفات دمياط'!$S$8:$S$5007=1)*'[1]عهد ومصروفات دمياط'!$T$8:$T$5007),0)) | F15: =IF($A15="","",N(D15)-N(E15)) | G15: 0 | H15: =IF($A15="","",IFERROR(SUMPRODUCT(('[1]عهد ومصروفات دمياط'!$H$8:$H$5007=$A15)*('[1]عهد ومصروفات دمياط'!$S$8:$S$5007=2)*'[1]عهد ومصروفات دمياط'!$T$8:$T$5007),0)) | I15: =IF($A15="","",N(G15)-N(H15)) | J15: 0 | K15: =IF($A15="","",IFERROR(SUMPRODUCT(('[1]عهد ومصروفات دمياط'!$H$8:$H$5007=$A15)*('[1]عهد ومصروفات دمياط'!$S$8:$S$5007=3)*'[1]عهد ومصروفات دمياط'!$T$8:$T$5007),0)) | L15: =IF($A15="","",N(J15)-N(K15)) | M15: 0 | N15: =IF($A15="","",IFERROR(SUMPRODUCT(('[1]عهد ومصروفات دمياط'!$H$8:$H$5007=$A15)*('[1]عهد ومصروفات دمياط'!$S$8:$S$5007=4)*'[1]عهد ومصروفات دمياط'!$T$8:$T$5007),0)) | O15: =IF($A15="","",N(M15)-N(N15)) | P15: 0 | Q15: =IF($A15="","",IFERROR(SUMPRODUCT(('[1]عهد ومصروفات دمياط'!$H$8:$H$5007=$A15)*('[1]عهد ومصروفات دمياط'!$S$8:$S$5007=5)*'[1]عهد ومصروفات دمياط'!$T$8:$T$5007),0)) | R15: =IF($A15="","",N(P15)-N(Q15)) | S15: 45000 | T15: =IF($A15="","",IFERROR(SUMPRODUCT(('[1]عهد ومصروفات دمياط'!$H$8:$H$5007=$A15)*('[1]عهد ومصروفات دمياط'!$S$8:$S$5007=6)*'[1]عهد ومصروفات دمياط'!$T$8:$T$5007),0)) | U15: =IF($A15="","",N(S15)-N(T15)) | V15: 45000 | W15: =IF($A15="","",IFERROR(SUMPRODUCT(('[1]عهد ومصروفات دمياط'!$H$8:$H$5007=$A15)*('[1]عهد ومصروفات دمياط'!$S$8:$S$5007=7)*'[1]عهد ومصروفات دمياط'!$T$8:$T$5007),0)) | X15: =IF($A15="","",N(V15)-N(W15)) | Y15: 0 | Z15: =IF($A15="","",IFERROR(SUMPRODUCT(('[1]عهد ومصروفات دمياط'!$H$8:$H$5007=$A15)*('[1]عهد ومصروفات دمياط'!$S$8:$S$5007=8)*'[1]عهد ومصروفات دمياط'!$T$8:$T$5007),0)) | AA15: =IF($A15="","",N(Y15)-N(Z15)) | AB15: 0 | AC15: =IF($A15="","",IFERROR(SUMPRODUCT(('[1]عهد ومصروفات دمياط'!$H$8:$H$5007=$A15)*('[1]عهد ومصروفات دمياط'!$S$8:$S$5007=9)*'[1]عهد ومصروفات دمياط'!$T$8:$T$5007),0)) | AD15: =IF($A15="","",N(AB15)-N(AC15)) | AE15: 0 | AF15: =IF($A15="","",IFERROR(SUMPRODUCT(('[1]عهد ومصروفات دمياط'!$H$8:$H$5007=$A15)*('[1]عهد ومصروفات دمياط'!$S$8:$S$5007=10)*'[1]عهد ومصروفات دمياط'!$T$8:$T$5007),0)) | AG15: =IF($A15="","",N(AE15)-N(AF15)) | AH15: 0 | AI15: =IF($A15="","",IFERROR(SUMPRODUCT(('[1]عهد ومصروفات دمياط'!$H$8:$H$5007=$A15)*('[1]عهد ومصروفات دمياط'!$S$8:$S$5007=11)*'[1]عهد ومصروفات دمياط'!$T$8:$T$5007),0)) | AJ15: =IF($A15="","",N(AH15)-N(AI15)) | AK15: 0 | AL15: =IF($A15="","",IFERROR(SUMPRODUCT(('[1]عهد ومصروفات دمياط'!$H$8:$H$5007=$A15)*('[1]عهد ومصروفات دمياط'!$S$8:$S$5007=12)*'[1]عهد ومصروفات دمياط'!$T$8:$T$5007),0)) | AM15: =IF($A15="","",N(AK15)-N(AL15)) | AN15: =IF(A15="","",N(D15)+N(G15)+N(J15)+N(M15)+N(P15)+N(S15)+N(V15)+N(Y15)+N(AB15)+N(AE15)+N(AH15)+N(AK15)) | AO15: =IF(A15="","",N(E15)+N(H15)+N(K15)+N(N15)+N(Q15)+N(T15)+N(W15)+N(Z15)+N(AC15)+N(AF15)+N(AI15)+N(AL15)) | AP15: =IF(A15="","",N(B15)-AO15) | AQ15: =IF(A15="",0,(N(F15)<0)+(N(I15)<0)+(N(L15)<0)+(N(O15)<0)+(N(R15)<0)+(N(U15)<0)+(N(X15)<0)+(N(AA15)<0)+(N(AD15)<0)+(N(AG15)<0)+(N(AJ15)<0)+(N(AM15)<0)) | AR15: =IF(A15="",0,MAX(0,-N(F15))+MAX(0,-N(I15))+MAX(0,-N(L15))+MAX(0,-N(O15))+MAX(0,-N(R15))+MAX(0,-N(U15))+MAX(0,-N(X15))+MAX(0,-N(AA15))+MAX(0,-N(AD15))+MAX(0,-N(AG15))+MAX(0,-N(AJ15))+MAX(0,-N(AM15))) | AS15: =IF(A15="",0,IF(OR(N(AP15)<0,AQ15>0),1,0)) | AT15: =AT14+AS15 | AU15: =IF(A15="",-1,N(AO15)+ROW()/10000000)
A16: انتقالات الموقع – الصف الثانى | B16: 135000 | C16: =IF(A16="","",N(B16)/12) | D16: 0 | E16: =IF($A16="","",IFERROR(SUMPRODUCT(('[1]عهد ومصروفات دمياط'!$H$8:$H$5007=$A16)*('[1]عهد ومصروفات دمياط'!$S$8:$S$5007=1)*'[1]عهد ومصروفات دمياط'!$T$8:$T$5007),0)) | F16: =IF($A16="","",N(D16)-N(E16)) | G16: 0 | H16: =IF($A16="","",IFERROR(SUMPRODUCT(('[1]عهد ومصروفات دمياط'!$H$8:$H$5007=$A16)*('[1]عهد ومصروفات دمياط'!$S$8:$S$5007=2)*'[1]عهد ومصروفات دمياط'!$T$8:$T$5007),0)) | I16: =IF($A16="","",N(G16)-N(H16)) | J16: 0 | K16: =IF($A16="","",IFERROR(SUMPRODUCT(('[1]عهد ومصروفات دمياط'!$H$8:$H$5007=$A16)*('[1]عهد ومصروفات دمياط'!$S$8:$S$5007=3)*'[1]عهد ومصروفات دمياط'!$T$8:$T$5007),0)) | L16: =IF($A16="","",N(J16)-N(K16)) | M16: 0 | N16: =IF($A16="","",IFERROR(SUMPRODUCT(('[1]عهد ومصروفات دمياط'!$H$8:$H$5007=$A16)*('[1]عهد ومصروفات دمياط'!$S$8:$S$5007=4)*'[1]عهد ومصروفات دمياط'!$T$8:$T$5007),0)) | O16: =IF($A16="","",N(M16)-N(N16)) | P16: 0 | Q16: =IF($A16="","",IFERROR(SUMPRODUCT(('[1]عهد ومصروفات دمياط'!$H$8:$H$5007=$A16)*('[1]عهد ومصروفات دمياط'!$S$8:$S$5007=5)*'[1]عهد ومصروفات دمياط'!$T$8:$T$5007),0)) | R16: =IF($A16="","",N(P16)-N(Q16)) | S16: 50000 | T16: =IF($A16="","",IFERROR(SUMPRODUCT(('[1]عهد ومصروفات دمياط'!$H$8:$H$5007=$A16)*('[1]عهد ومصروفات دمياط'!$S$8:$S$5007=6)*'[1]عهد ومصروفات دمياط'!$T$8:$T$5007),0)) | U16: =IF($A16="","",N(S16)-N(T16)) | V16: 85000 | W16: =IF($A16="","",IFERROR(SUMPRODUCT(('[1]عهد ومصروفات دمياط'!$H$8:$H$5007=$A16)*('[1]عهد ومصروفات دمياط'!$S$8:$S$5007=7)*'[1]عهد ومصروفات دمياط'!$T$8:$T$5007),0)) | X16: =IF($A16="","",N(V16)-N(W16)) | Y16: 0 | Z16: =IF($A16="","",IFERROR(SUMPRODUCT(('[1]عهد ومصروفات دمياط'!$H$8:$H$5007=$A16)*('[1]عهد ومصروفات دمياط'!$S$8:$S$5007=8)*'[1]عهد ومصروفات دمياط'!$T$8:$T$5007),0)) | AA16: =IF($A16="","",N(Y16)-N(Z16)) | AB16: 0 | AC16: =IF($A16="","",IFERROR(SUMPRODUCT(('[1]عهد ومصروفات دمياط'!$H$8:$H$5007=$A16)*('[1]عهد ومصروفات دمياط'!$S$8:$S$5007=9)*'[1]عهد ومصروفات دمياط'!$T$8:$T$5007),0)) | AD16: =IF($A16="","",N(AB16)-N(AC16)) | AE16: 0 | AF16: =IF($A16="","",IFERROR(SUMPRODUCT(('[1]عهد ومصروفات دمياط'!$H$8:$H$5007=$A16)*('[1]عهد ومصروفات دمياط'!$S$8:$S$5007=10)*'[1]عهد ومصروفات دمياط'!$T$8:$T$5007),0)) | AG16: =IF($A16="","",N(AE16)-N(AF16)) | AH16: 0 | AI16: =IF($A16="","",IFERROR(SUMPRODUCT(('[1]عهد ومصروفات دمياط'!$H$8:$H$5007=$A16)*('[1]عهد ومصروفات دمياط'!$S$8:$S$5007=11)*'[1]عهد ومصروفات دمياط'!$T$8:$T$5007),0)) | AJ16: =IF($A16="","",N(AH16)-N(AI16)) | AK16: 0 | AL16: =IF($A16="","",IFERROR(SUMPRODUCT(('[1]عهد ومصروفات دمياط'!$H$8:$H$5007=$A16)*('[1]عهد ومصروفات دمياط'!$S$8:$S$5007=12)*'[1]عهد ومصروفات دمياط'!$T$8:$T$5007),0)) | AM16: =IF($A16="","",N(AK16)-N(AL16)) | AN16: =IF(A16="","",N(D16)+N(G16)+N(J16)+N(M16)+N(P16)+N(S16)+N(V16)+N(Y16)+N(AB16)+N(AE16)+N(AH16)+N(AK16)) | AO16: =IF(A16="","",N(E16)+N(H16)+N(K16)+N(N16)+N(Q16)+N(T16)+N(W16)+N(Z16)+N(AC16)+N(AF16)+N(AI16)+N(AL16)) | AP16: =IF(A16="","",N(B16)-AO16) | AQ16: =IF(A16="",0,(N(F16)<0)+(N(I16)<0)+(N(L16)<0)+(N(O16)<0)+(N(R16)<0)+(N(U16)<0)+(N(X16)<0)+(N(AA16)<0)+(N(AD16)<0)+(N(AG16)<0)+(N(AJ16)<0)+(N(AM16)<0)) | AR16: =IF(A16="",0,MAX(0,-N(F16))+MAX(0,-N(I16))+MAX(0,-N(L16))+MAX(0,-N(O16))+MAX(0,-N(R16))+MAX(0,-N(U16))+MAX(0,-N(X16))+MAX(0,-N(AA16))+MAX(0,-N(AD16))+MAX(0,-N(AG16))+MAX(0,-N(AJ16))+MAX(0,-N(AM16))) | AS16: =IF(A16="",0,IF(OR(N(AP16)<0,AQ16>0),1,0)) | AT16: =AT15+AS16 | AU16: =IF(A16="",-1,N(AO16)+ROW()/10000000)
A17: وجبات الموقع – الصف الأول | B17: 59400 | C17: =IF(A17="","",N(B17)/12) | D17: 0 | E17: =IF($A17="","",IFERROR(SUMPRODUCT(('[1]عهد ومصروفات دمياط'!$H$8:$H$5007=$A17)*('[1]عهد ومصروفات دمياط'!$S$8:$S$5007=1)*'[1]عهد ومصروفات دمياط'!$T$8:$T$5007),0)) | F17: =IF($A17="","",N(D17)-N(E17)) | G17: 0 | H17: =IF($A17="","",IFERROR(SUMPRODUCT(('[1]عهد ومصروفات دمياط'!$H$8:$H$5007=$A17)*('[1]عهد ومصروفات دمياط'!$S$8:$S$5007=2)*'[1]عهد ومصروفات دمياط'!$T$8:$T$5007),0)) | I17: =IF($A17="","",N(G17)-N(H17)) | J17: 0 | K17: =IF($A17="","",IFERROR(SUMPRODUCT(('[1]عهد ومصروفات دمياط'!$H$8:$H$5007=$A17)*('[1]عهد ومصروفات دمياط'!$S$8:$S$5007=3)*'[1]عهد ومصروفات دمياط'!$T$8:$T$5007),0)) | L17: =IF($A17="","",N(J17)-N(K17)) | M17: 0 | N17: =IF($A17="","",IFERROR(SUMPRODUCT(('[1]عهد ومصروفات دمياط'!$H$8:$H$5007=$A17)*('[1]عهد ومصروفات دمياط'!$S$8:$S$5007=4)*'[1]عهد ومصروفات دمياط'!$T$8:$T$5007),0)) | O17: =IF($A17="","",N(M17)-N(N17)) | P17: 0 | Q17: =IF($A17="","",IFERROR(SUMPRODUCT(('[1]عهد ومصروفات دمياط'!$H$8:$H$5007=$A17)*('[1]عهد ومصروفات دمياط'!$S$8:$S$5007=5)*'[1]عهد ومصروفات دمياط'!$T$8:$T$5007),0)) | R17: =IF($A17="","",N(P17)-N(Q17)) | S17: 29700 | T17: =IF($A17="","",IFERROR(SUMPRODUCT(('[1]عهد ومصروفات دمياط'!$H$8:$H$5007=$A17)*('[1]عهد ومصروفات دمياط'!$S$8:$S$5007=6)*'[1]عهد ومصروفات دمياط'!$T$8:$T$5007),0)) | U17: =IF($A17="","",N(S17)-N(T17)) | V17: 29700 | W17: =IF($A17="","",IFERROR(SUMPRODUCT(('[1]عهد ومصروفات دمياط'!$H$8:$H$5007=$A17)*('[1]عهد ومصروفات دمياط'!$S$8:$S$5007=7)*'[1]عهد ومصروفات دمياط'!$T$8:$T$5007),0)) | X17: =IF($A17="","",N(V17)-N(W17)) | Y17: 0 | Z17: =IF($A17="","",IFERROR(SUMPRODUCT(('[1]عهد ومصروفات دمياط'!$H$8:$H$5007=$A17)*('[1]عهد ومصروفات دمياط'!$S$8:$S$5007=8)*'[1]عهد ومصروفات دمياط'!$T$8:$T$5007),0)) | AA17: =IF($A17="","",N(Y17)-N(Z17)) | AB17: 0 | AC17: =IF($A17="","",IFERROR(SUMPRODUCT(('[1]عهد ومصروفات دمياط'!$H$8:$H$5007=$A17)*('[1]عهد ومصروفات دمياط'!$S$8:$S$5007=9)*'[1]عهد ومصروفات دمياط'!$T$8:$T$5007),0)) | AD17: =IF($A17="","",N(AB17)-N(AC17)) | AE17: 0 | AF17: =IF($A17="","",IFERROR(SUMPRODUCT(('[1]عهد ومصروفات دمياط'!$H$8:$H$5007=$A17)*('[1]عهد ومصروفات دمياط'!$S$8:$S$5007=10)*'[1]عهد ومصروفات دمياط'!$T$8:$T$5007),0)) | AG17: =IF($A17="","",N(AE17)-N(AF17)) | AH17: 0 | AI17: =IF($A17="","",IFERROR(SUMPRODUCT(('[1]عهد ومصروفات دمياط'!$H$8:$H$5007=$A17)*('[1]عهد ومصروفات دمياط'!$S$8:$S$5007=11)*'[1]عهد ومصروفات دمياط'!$T$8:$T$5007),0)) | AJ17: =IF($A17="","",N(AH17)-N(AI17)) | AK17: 0 | AL17: =IF($A17="","",IFERROR(SUMPRODUCT(('[1]عهد ومصروفات دمياط'!$H$8:$H$5007=$A17)*('[1]عهد ومصروفات دمياط'!$S$8:$S$5007=12)*'[1]عهد ومصروفات دمياط'!$T$8:$T$5007),0)) | AM17: =IF($A17="","",N(AK17)-N(AL17)) | AN17: =IF(A17="","",N(D17)+N(G17)+N(J17)+N(M17)+N(P17)+N(S17)+N(V17)+N(Y17)+N(AB17)+N(AE17)+N(AH17)+N(AK17)) | AO17: =IF(A17="","",N(E17)+N(H17)+N(K17)+N(N17)+N(Q17)+N(T17)+N(W17)+N(Z17)+N(AC17)+N(AF17)+N(AI17)+N(AL17)) | AP17: =IF(A17="","",N(B17)-AO17) | AQ17: =IF(A17="",0,(N(F17)<0)+(N(I17)<0)+(N(L17)<0)+(N(O17)<0)+(N(R17)<0)+(N(U17)<0)+(N(X17)<0)+(N(AA17)<0)+(N(AD17)<0)+(N(AG17)<0)+(N(AJ17)<0)+(N(AM17)<0)) | AR17: =IF(A17="",0,MAX(0,-N(F17))+MAX(0,-N(I17))+MAX(0,-N(L17))+MAX(0,-N(O17))+MAX(0,-N(R17))+MAX(0,-N(U17))+MAX(0,-N(X17))+MAX(0,-N(AA17))+MAX(0,-N(AD17))+MAX(0,-N(AG17))+MAX(0,-N(AJ17))+MAX(0,-N(AM17))) | AS17: =IF(A17="",0,IF(OR(N(AP17)<0,AQ17>0),1,0)) | AT17: =AT16+AS17 | AU17: =IF(A17="",-1,N(AO17)+ROW()/10000000)
A18: وجبات الموقع – الصف الثانى | B18: 56100 | C18: =IF(A18="","",N(B18)/12) | D18: 0 | E18: =IF($A18="","",IFERROR(SUMPRODUCT(('[1]عهد ومصروفات دمياط'!$H$8:$H$5007=$A18)*('[1]عهد ومصروفات دمياط'!$S$8:$S$5007=1)*'[1]عهد ومصروفات دمياط'!$T$8:$T$5007),0)) | F18: =IF($A18="","",N(D18)-N(E18)) | G18: 0 | H18: =IF($A18="","",IFERROR(SUMPRODUCT(('[1]عهد ومصروفات دمياط'!$H$8:$H$5007=$A18)*('[1]عهد ومصروفات دمياط'!$S$8:$S$5007=2)*'[1]عهد ومصروفات دمياط'!$T$8:$T$5007),0)) | I18: =IF($A18="","",N(G18)-N(H18)) | J18: 0 | K18: =IF($A18="","",IFERROR(SUMPRODUCT(('[1]عهد ومصروفات دمياط'!$H$8:$H$5007=$A18)*('[1]عهد ومصروفات دمياط'!$S$8:$S$5007=3)*'[1]عهد ومصروفات دمياط'!$T$8:$T$5007),0)) | L18: =IF($A18="","",N(J18)-N(K18)) | M18: 0 | N18: =IF($A18="","",IFERROR(SUMPRODUCT(('[1]عهد ومصروفات دمياط'!$H$8:$H$5007=$A18)*('[1]عهد ومصروفات دمياط'!$S$8:$S$5007=4)*'[1]عهد ومصروفات دمياط'!$T$8:$T$5007),0)) | O18: =IF($A18="","",N(M18)-N(N18)) | P18: 0 | Q18: =IF($A18="","",IFERROR(SUMPRODUCT(('[1]عهد ومصروفات دمياط'!$H$8:$H$5007=$A18)*('[1]عهد ومصروفات دمياط'!$S$8:$S$5007=5)*'[1]عهد ومصروفات دمياط'!$T$8:$T$5007),0)) | R18: =IF($A18="","",N(P18)-N(Q18)) | S18: 20777.778 | T18: =IF($A18="","",IFERROR(SUMPRODUCT(('[1]عهد ومصروفات دمياط'!$H$8:$H$5007=$A18)*('[1]عهد ومصروفات دمياط'!$S$8:$S$5007=6)*'[1]عهد ومصروفات دمياط'!$T$8:$T$5007),0)) | U18: =IF($A18="","",N(S18)-N(T18)) | V18: 35322.222 | W18: =IF($A18="","",IFERROR(SUMPRODUCT(('[1]عهد ومصروفات دمياط'!$H$8:$H$5007=$A18)*('[1]عهد ومصروفات دمياط'!$S$8:$S$5007=7)*'[1]عهد ومصروفات دمياط'!$T$8:$T$5007),0)) | X18: =IF($A18="","",N(V18)-N(W18)) | Y18: 0 | Z18: =IF($A18="","",IFERROR(SUMPRODUCT(('[1]عهد ومصروفات دمياط'!$H$8:$H$5007=$A18)*('[1]عهد ومصروفات دمياط'!$S$8:$S$5007=8)*'[1]عهد ومصروفات دمياط'!$T$8:$T$5007),0)) | AA18: =IF($A18="","",N(Y18)-N(Z18)) | AB18: 0 | AC18: =IF($A18="","",IFERROR(SUMPRODUCT(('[1]عهد ومصروفات دمياط'!$H$8:$H$5007=$A18)*('[1]عهد ومصروفات دمياط'!$S$8:$S$5007=9)*'[1]عهد ومصروفات دمياط'!$T$8:$T$5007),0)) | AD18: =IF($A18="","",N(AB18)-N(AC18)) | AE18: 0 | AF18: =IF($A18="","",IFERROR(SUMPRODUCT(('[1]عهد ومصروفات دمياط'!$H$8:$H$5007=$A18)*('[1]عهد ومصروفات دمياط'!$S$8:$S$5007=10)*'[1]عهد ومصروفات دمياط'!$T$8:$T$5007),0)) | AG18: =IF($A18="","",N(AE18)-N(AF18)) | AH18: 0 | AI18: =IF($A18="","",IFERROR(SUMPRODUCT(('[1]عهد ومصروفات دمياط'!$H$8:$H$5007=$A18)*('[1]عهد ومصروفات دمياط'!$S$8:$S$5007=11)*'[1]عهد ومصروفات دمياط'!$T$8:$T$5007),0)) | AJ18: =IF($A18="","",N(AH18)-N(AI18)) | AK18: 0 | AL18: =IF($A18="","",IFERROR(SUMPRODUCT(('[1]عهد ومصروفات دمياط'!$H$8:$H$5007=$A18)*('[1]عهد ومصروفات دمياط'!$S$8:$S$5007=12)*'[1]عهد ومصروفات دمياط'!$T$8:$T$5007),0)) | AM18: =IF($A18="","",N(AK18)-N(AL18)) | AN18: =IF(A18="","",N(D18)+N(G18)+N(J18)+N(M18)+N(P18)+N(S18)+N(V18)+N(Y18)+N(AB18)+N(AE18)+N(AH18)+N(AK18)) | AO18: =IF(A18="","",N(E18)+N(H18)+N(K18)+N(N18)+N(Q18)+N(T18)+N(W18)+N(Z18)+N(AC18)+N(AF18)+N(AI18)+N(AL18)) | AP18: =IF(A18="","",N(B18)-AO18) | AQ18: =IF(A18="",0,(N(F18)<0)+(N(I18)<0)+(N(L18)<0)+(N(O18)<0)+(N(R18)<0)+(N(U18)<0)+(N(X18)<0)+(N(AA18)<0)+(N(AD18)<0)+(N(AG18)<0)+(N(AJ18)<0)+(N(AM18)<0)) | AR18: =IF(A18="",0,MAX(0,-N(F18))+MAX(0,-N(I18))+MAX(0,-N(L18))+MAX(0,-N(O18))+MAX(0,-N(R18))+MAX(0,-N(U18))+MAX(0,-N(X18))+MAX(0,-N(AA18))+MAX(0,-N(AD18))+MAX(0,-N(AG18))+MAX(0,-N(AJ18))+MAX(0,-N(AM18))) | AS18: =IF(A18="",0,IF(OR(N(AP18)<0,AQ18>0),1,0)) | AT18: =AT17+AS18 | AU18: =IF(A18="",-1,N(AO18)+ROW()/10000000)
A19: التأمين على الطلاب والعاملين | B19: 42750 | C19: =IF(A19="","",N(B19)/12) | D19: 42750 | E19: =IF($A19="","",IFERROR(SUMPRODUCT(('[1]عهد ومصروفات دمياط'!$H$8:$H$5007=$A19)*('[1]عهد ومصروفات دمياط'!$S$8:$S$5007=1)*'[1]عهد ومصروفات دمياط'!$T$8:$T$5007),0)) | F19: =IF($A19="","",N(D19)-N(E19)) | G19: 0 | H19: =IF($A19="","",IFERROR(SUMPRODUCT(('[1]عهد ومصروفات دمياط'!$H$8:$H$5007=$A19)*('[1]عهد ومصروفات دمياط'!$S$8:$S$5007=2)*'[1]عهد ومصروفات دمياط'!$T$8:$T$5007),0)) | I19: =IF($A19="","",N(G19)-N(H19)) | J19: 0 | K19: =IF($A19="","",IFERROR(SUMPRODUCT(('[1]عهد ومصروفات دمياط'!$H$8:$H$5007=$A19)*('[1]عهد ومصروفات دمياط'!$S$8:$S$5007=3)*'[1]عهد ومصروفات دمياط'!$T$8:$T$5007),0)) | L19: =IF($A19="","",N(J19)-N(K19)) | M19: 0 | N19: =IF($A19="","",IFERROR(SUMPRODUCT(('[1]عهد ومصروفات دمياط'!$H$8:$H$5007=$A19)*('[1]عهد ومصروفات دمياط'!$S$8:$S$5007=4)*'[1]عهد ومصروفات دمياط'!$T$8:$T$5007),0)) | O19: =IF($A19="","",N(M19)-N(N19)) | P19: 0 | Q19: =IF($A19="","",IFERROR(SUMPRODUCT(('[1]عهد ومصروفات دمياط'!$H$8:$H$5007=$A19)*('[1]عهد ومصروفات دمياط'!$S$8:$S$5007=5)*'[1]عهد ومصروفات دمياط'!$T$8:$T$5007),0)) | R19: =IF($A19="","",N(P19)-N(Q19)) | S19: 0 | T19: =IF($A19="","",IFERROR(SUMPRODUCT(('[1]عهد ومصروفات دمياط'!$H$8:$H$5007=$A19)*('[1]عهد ومصروفات دمياط'!$S$8:$S$5007=6)*'[1]عهد ومصروفات دمياط'!$T$8:$T$5007),0)) | U19: =IF($A19="","",N(S19)-N(T19)) | V19: 0 | W19: =IF($A19="","",IFERROR(SUMPRODUCT(('[1]عهد ومصروفات دمياط'!$H$8:$H$5007=$A19)*('[1]عهد ومصروفات دمياط'!$S$8:$S$5007=7)*'[1]عهد ومصروفات دمياط'!$T$8:$T$5007),0)) | X19: =IF($A19="","",N(V19)-N(W19)) | Y19: 0 | Z19: =IF($A19="","",IFERROR(SUMPRODUCT(('[1]عهد ومصروفات دمياط'!$H$8:$H$5007=$A19)*('[1]عهد ومصروفات دمياط'!$S$8:$S$5007=8)*'[1]عهد ومصروفات دمياط'!$T$8:$T$5007),0)) | AA19: =IF($A19="","",N(Y19)-N(Z19)) | AB19: 0 | AC19: =IF($A19="","",IFERROR(SUMPRODUCT(('[1]عهد ومصروفات دمياط'!$H$8:$H$5007=$A19)*('[1]عهد ومصروفات دمياط'!$S$8:$S$5007=9)*'[1]عهد ومصروفات دمياط'!$T$8:$T$5007),0)) | AD19: =IF($A19="","",N(AB19)-N(AC19)) | AE19: 0 | AF19: =IF($A19="","",IFERROR(SUMPRODUCT(('[1]عهد ومصروفات دمياط'!$H$8:$H$5007=$A19)*('[1]عهد ومصروفات دمياط'!$S$8:$S$5007=10)*'[1]عهد ومصروفات دمياط'!$T$8:$T$5007),0)) | AG19: =IF($A19="","",N(AE19)-N(AF19)) | AH19: 0 | AI19: =IF($A19="","",IFERROR(SUMPRODUCT(('[1]عهد ومصروفات دمياط'!$H$8:$H$5007=$A19)*('[1]عهد ومصروفات دمياط'!$S$8:$S$5007=11)*'[1]عهد ومصروفات دمياط'!$T$8:$T$5007),0)) | AJ19: =IF($A19="","",N(AH19)-N(AI19)) | AK19: 0 | AL19: =IF($A19="","",IFERROR(SUMPRODUCT(('[1]عهد ومصروفات دمياط'!$H$8:$H$5007=$A19)*('[1]عهد ومصروفات دمياط'!$S$8:$S$5007=12)*'[1]عهد ومصروفات دمياط'!$T$8:$T$5007),0)) | AM19: =IF($A19="","",N(AK19)-N(AL19)) | AN19: =IF(A19="","",N(D19)+N(G19)+N(J19)+N(M19)+N(P19)+N(S19)+N(V19)+N(Y19)+N(AB19)+N(AE19)+N(AH19)+N(AK19)) | AO19: =IF(A19="","",N(E19)+N(H19)+N(K19)+N(N19)+N(Q19)+N(T19)+N(W19)+N(Z19)+N(AC19)+N(AF19)+N(AI19)+N(AL19)) | AP19: =IF(A19="","",N(B19)-AO19) | AQ19: =IF(A19="",0,(N(F19)<0)+(N(I19)<0)+(N(L19)<0)+(N(O19)<0)+(N(R19)<0)+(N(U19)<0)+(N(X19)<0)+(N(AA19)<0)+(N(AD19)<0)+(N(AG19)<0)+(N(AJ19)<0)+(N(AM19)<0)) | AR19: =IF(A19="",0,MAX(0,-N(F19))+MAX(0,-N(I19))+MAX(0,-N(L19))+MAX(0,-N(O19))+MAX(0,-N(R19))+MAX(0,-N(U19))+MAX(0,-N(X19))+MAX(0,-N(AA19))+MAX(0,-N(AD19))+MAX(0,-N(AG19))+MAX(0,-N(AJ19))+MAX(0,-N(AM19))) | AS19: =IF(A19="",0,IF(OR(N(AP19)<0,AQ19>0),1,0)) | AT19: =AT18+AS19 | AU19: =IF(A19="",-1,N(AO19)+ROW()/10000000)
A20: حافز برنامج المهارات الحياتية (سمات) | B20: 100000 | C20: =IF(A20="","",N(B20)/12) | D20: 10000 | E20: =IF($A20="","",IFERROR(SUMPRODUCT(('[1]عهد ومصروفات دمياط'!$H$8:$H$5007=$A20)*('[1]عهد ومصروفات دمياط'!$S$8:$S$5007=1)*'[1]عهد ومصروفات دمياط'!$T$8:$T$5007),0)) | F20: =IF($A20="","",N(D20)-N(E20)) | G20: 10000 | H20: =IF($A20="","",IFERROR(SUMPRODUCT(('[1]عهد ومصروفات دمياط'!$H$8:$H$5007=$A20)*('[1]عهد ومصروفات دمياط'!$S$8:$S$5007=2)*'[1]عهد ومصروفات دمياط'!$T$8:$T$5007),0)) | I20: =IF($A20="","",N(G20)-N(H20)) | J20: 10000 | K20: =IF($A20="","",IFERROR(SUMPRODUCT(('[1]عهد ومصروفات دمياط'!$H$8:$H$5007=$A20)*('[1]عهد ومصروفات دمياط'!$S$8:$S$5007=3)*'[1]عهد ومصروفات دمياط'!$T$8:$T$5007),0)) | L20: =IF($A20="","",N(J20)-N(K20)) | M20: 10000 | N20: =IF($A20="","",IFERROR(SUMPRODUCT(('[1]عهد ومصروفات دمياط'!$H$8:$H$5007=$A20)*('[1]عهد ومصروفات دمياط'!$S$8:$S$5007=4)*'[1]عهد ومصروفات دمياط'!$T$8:$T$5007),0)) | O20: =IF($A20="","",N(M20)-N(N20)) | P20: 15000 | Q20: =IF($A20="","",IFERROR(SUMPRODUCT(('[1]عهد ومصروفات دمياط'!$H$8:$H$5007=$A20)*('[1]عهد ومصروفات دمياط'!$S$8:$S$5007=5)*'[1]عهد ومصروفات دمياط'!$T$8:$T$5007),0)) | R20: =IF($A20="","",N(P20)-N(Q20)) | S20: 15000 | T20: =IF($A20="","",IFERROR(SUMPRODUCT(('[1]عهد ومصروفات دمياط'!$H$8:$H$5007=$A20)*('[1]عهد ومصروفات دمياط'!$S$8:$S$5007=6)*'[1]عهد ومصروفات دمياط'!$T$8:$T$5007),0)) | U20: =IF($A20="","",N(S20)-N(T20)) | V20: 15000 | W20: =IF($A20="","",IFERROR(SUMPRODUCT(('[1]عهد ومصروفات دمياط'!$H$8:$H$5007=$A20)*('[1]عهد ومصروفات دمياط'!$S$8:$S$5007=7)*'[1]عهد ومصروفات دمياط'!$T$8:$T$5007),0)) | X20: =IF($A20="","",N(V20)-N(W20)) | Y20: 15000 | Z20: =IF($A20="","",IFERROR(SUMPRODUCT(('[1]عهد ومصروفات دمياط'!$H$8:$H$5007=$A20)*('[1]عهد ومصروفات دمياط'!$S$8:$S$5007=8)*'[1]عهد ومصروفات دمياط'!$T$8:$T$5007),0)) | AA20: =IF($A20="","",N(Y20)-N(Z20)) | AB20: 0 | AC20: =IF($A20="","",IFERROR(SUMPRODUCT(('[1]عهد ومصروفات دمياط'!$H$8:$H$5007=$A20)*('[1]عهد ومصروفات دمياط'!$S$8:$S$5007=9)*'[1]عهد ومصروفات دمياط'!$T$8:$T$5007),0)) | AD20: =IF($A20="","",N(AB20)-N(AC20)) | AE20: 0 | AF20: =IF($A20="","",IFERROR(SUMPRODUCT(('[1]عهد ومصروفات دمياط'!$H$8:$H$5007=$A20)*('[1]عهد ومصروفات دمياط'!$S$8:$S$5007=10)*'[1]عهد ومصروفات دمياط'!$T$8:$T$5007),0)) | AG20: =IF($A20="","",N(AE20)-N(AF20)) | AH20: 0 | AI20: =IF($A20="","",IFERROR(SUMPRODUCT(('[1]عهد ومصروفات دمياط'!$H$8:$H$5007=$A20)*('[1]عهد ومصروفات دمياط'!$S$8:$S$5007=11)*'[1]عهد ومصروفات دمياط'!$T$8:$T$5007),0)) | AJ20: =IF($A20="","",N(AH20)-N(AI20)) | AK20: 0 | AL20: =IF($A20="","",IFERROR(SUMPRODUCT(('[1]عهد ومصروفات دمياط'!$H$8:$H$5007=$A20)*('[1]عهد ومصروفات دمياط'!$S$8:$S$5007=12)*'[1]عهد ومصروفات دمياط'!$T$8:$T$5007),0)) | AM20: =IF($A20="","",N(AK20)-N(AL20)) | AN20: =IF(A20="","",N(D20)+N(G20)+N(J20)+N(M20)+N(P20)+N(S20)+N(V20)+N(Y20)+N(AB20)+N(AE20)+N(AH20)+N(AK20)) | AO20: =IF(A20="","",N(E20)+N(H20)+N(K20)+N(N20)+N(Q20)+N(T20)+N(W20)+N(Z20)+N(AC20)+N(AF20)+N(AI20)+N(AL20)) | AP20: =IF(A20="","",N(B20)-AO20) | AQ20: =IF(A20="",0,(N(F20)<0)+(N(I20)<0)+(N(L20)<0)+(N(O20)<0)+(N(R20)<0)+(N(U20)<0)+(N(X20)<0)+(N(AA20)<0)+(N(AD20)<0)+(N(AG20)<0)+(N(AJ20)<0)+(N(AM20)<0)) | AR20: =IF(A20="",0,MAX(0,-N(F20))+MAX(0,-N(I20))+MAX(0,-N(L20))+MAX(0,-N(O20))+MAX(0,-N(R20))+MAX(0,-N(U20))+MAX(0,-N(X20))+MAX(0,-N(AA20))+MAX(0,-N(AD20))+MAX(0,-N(AG20))+MAX(0,-N(AJ20))+MAX(0,-N(AM20))) | AS20: =IF(A20="",0,IF(OR(N(AP20)<0,AQ20>0),1,0)) | AT20: =AT19+AS20 | AU20: =IF(A20="",-1,N(AO20)+ROW()/10000000)
... A39: تكلفة الاعتماد الدولى والمراجعة الخارجية | B39: 0 | C39: =IF(A39="","",N(B39)/12) | D39: 0 | E39: =IF($A39="","",IFERROR(SUMPRODUCT(('[1]عهد ومصروفات دمياط'!$H$8:$H$5007=$A39)*('[1]عهد ومصروفات دمياط'!$S$8:$S$5007=1)*'[1]عهد ومصروفات دمياط'!$T$8:$T$5007),0)) | F39: =IF($A39="","",N(D39)-N(E39)) | G39: 0 | H39: =IF($A39="","",IFERROR(SUMPRODUCT(('[1]عهد ومصروفات دمياط'!$H$8:$H$5007=$A39)*('[1]عهد ومصروفات دمياط'!$S$8:$S$5007=2)*'[1]عهد ومصروفات دمياط'!$T$8:$T$5007),0)) | I39: =IF($A39="","",N(G39)-N(H39)) | J39: 0 | K39: =IF($A39="","",IFERROR(SUMPRODUCT(('[1]عهد ومصروفات دمياط'!$H$8:$H$5007=$A39)*('[1]عهد ومصروفات دمياط'!$S$8:$S$5007=3)*'[1]عهد ومصروفات دمياط'!$T$8:$T$5007),0)) | L39: =IF($A39="","",N(J39)-N(K39)) | M39: 0 | N39: =IF($A39="","",IFERROR(SUMPRODUCT(('[1]عهد ومصروفات دمياط'!$H$8:$H$5007=$A39)*('[1]عهد ومصروفات دمياط'!$S$8:$S$5007=4)*'[1]عهد ومصروفات دمياط'!$T$8:$T$5007),0)) | O39: =IF($A39="","",N(M39)-N(N39)) | P39: 0 | Q39: =IF($A39="","",IFERROR(SUMPRODUCT(('[1]عهد ومصروفات دمياط'!$H$8:$H$5007=$A39)*('[1]عهد ومصروفات دمياط'!$S$8:$S$5007=5)*'[1]عهد ومصروفات دمياط'!$T$8:$T$5007),0)) | R39: =IF($A39="","",N(P39)-N(Q39)) | S39: 0 | T39: =IF($A39="","",IFERROR(SUMPRODUCT(('[1]عهد ومصروفات دمياط'!$H$8:$H$5007=$A39)*('[1]عهد ومصروفات دمياط'!$S$8:$S$5007=6)*'[1]عهد ومصروفات دمياط'!$T$8:$T$5007),0)) | U39: =IF($A39="","",N(S39)-N(T39)) | V39: 0 | W39: =IF($A39="","",IFERROR(SUMPRODUCT(('[1]عهد ومصروفات دمياط'!$H$8:$H$5007=$A39)*('[1]عهد ومصروفات دمياط'!$S$8:$S$5007=7)*'[1]عهد ومصروفات دمياط'!$T$8:$T$5007),0)) | X39: =IF($A39="","",N(V39)-N(W39)) | Y39: 0 | Z39: =IF($A39="","",IFERROR(SUMPRODUCT(('[1]عهد ومصروفات دمياط'!$H$8:$H$5007=$A39)*('[1]عهد ومصروفات دمياط'!$S$8:$S$5007=8)*'[1]عهد ومصروفات دمياط'!$T$8:$T$5007),0)) | AA39: =IF($A39="","",N(Y39)-N(Z39)) | AB39: 0 | AC39: =IF($A39="","",IFERROR(SUMPRODUCT(('[1]عهد ومصروفات دمياط'!$H$8:$H$5007=$A39)*('[1]عهد ومصروفات دمياط'!$S$8:$S$5007=9)*'[1]عهد ومصروفات دمياط'!$T$8:$T$5007),0)) | AD39: =IF($A39="","",N(AB39)-N(AC39)) | AE39: 0 | AF39: =IF($A39="","",IFERROR(SUMPRODUCT(('[1]عهد ومصروفات دمياط'!$H$8:$H$5007=$A39)*('[1]عهد ومصروفات دمياط'!$S$8:$S$5007=10)*'[1]عهد ومصروفات دمياط'!$T$8:$T$5007),0)) | AG39: =IF($A39="","",N(AE39)-N(AF39)) | AH39: 0 | AI39: =IF($A39="","",IFERROR(SUMPRODUCT(('[1]عهد ومصروفات دمياط'!$H$8:$H$5007=$A39)*('[1]عهد ومصروفات دمياط'!$S$8:$S$5007=11)*'[1]عهد ومصروفات دمياط'!$T$8:$T$5007),0)) | AJ39: =IF($A39="","",N(AH39)-N(AI39)) | AK39: 0 | AL39: =IF($A39="","",IFERROR(SUMPRODUCT(('[1]عهد ومصروفات دمياط'!$H$8:$H$5007=$A39)*('[1]عهد ومصروفات دمياط'!$S$8:$S$5007=12)*'[1]عهد ومصروفات دمياط'!$T$8:$T$5007),0)) | AM39: =IF($A39="","",N(AK39)-N(AL39)) | AN39: =IF(A39="","",N(D39)+N(G39)+N(J39)+N(M39)+N(P39)+N(S39)+N(V39)+N(Y39)+N(AB39)+N(AE39)+N(AH39)+N(AK39)) | AO39: =IF(A39="","",N(E39)+N(H39)+N(K39)+N(N39)+N(Q39)+N(T39)+N(W39)+N(Z39)+N(AC39)+N(AF39)+N(AI39)+N(AL39)) | AP39: =IF(A39="","",N(B39)-AO39) | AQ39: =IF(A39="",0,(N(F39)<0)+(N(I39)<0)+(N(L39)<0)+(N(O39)<0)+(N(R39)<0)+(N(U39)<0)+(N(X39)<0)+(N(AA39)<0)+(N(AD39)<0)+(N(AG39)<0)+(N(AJ39)<0)+(N(AM39)<0)) | AR39: =IF(A39="",0,MAX(0,-N(F39))+MAX(0,-N(I39))+MAX(0,-N(L39))+MAX(0,-N(O39))+MAX(0,-N(R39))+MAX(0,-N(U39))+MAX(0,-N(X39))+MAX(0,-N(AA39))+MAX(0,-N(AD39))+MAX(0,-N(AG39))+MAX(0,-N(AJ39))+MAX(0,-N(AM39))) | AS39: =IF(A39="",0,IF(OR(N(AP39)<0,AQ39>0),1,0)) | AT39: =AT38+AS39 | AU39: =IF(A39="",-1,N(AO39)+ROW()/10000000)
C40: =IF(A40="","",N(B40)/12) | E40: =IF($A40="","",IFERROR(SUMPRODUCT(('[1]عهد ومصروفات دمياط'!$H$8:$H$5007=$A40)*('[1]عهد ومصروفات دمياط'!$S$8:$S$5007=1)*'[1]عهد ومصروفات دمياط'!$T$8:$T$5007),0)) | F40: =IF($A40="","",N(D40)-N(E40)) | H40: =IF($A40="","",IFERROR(SUMPRODUCT(('[1]عهد ومصروفات دمياط'!$H$8:$H$5007=$A40)*('[1]عهد ومصروفات دمياط'!$S$8:$S$5007=2)*'[1]عهد ومصروفات دمياط'!$T$8:$T$5007),0)) | I40: =IF($A40="","",N(G40)-N(H40)) | K40: =IF($A40="","",IFERROR(SUMPRODUCT(('[1]عهد ومصروفات دمياط'!$H$8:$H$5007=$A40)*('[1]عهد ومصروفات دمياط'!$S$8:$S$5007=3)*'[1]عهد ومصروفات دمياط'!$T$8:$T$5007),0)) | L40: =IF($A40="","",N(J40)-N(K40)) | N40: =IF($A40="","",IFERROR(SUMPRODUCT(('[1]عهد ومصروفات دمياط'!$H$8:$H$5007=$A40)*('[1]عهد ومصروفات دمياط'!$S$8:$S$5007=4)*'[1]عهد ومصروفات دمياط'!$T$8:$T$5007),0)) | O40: =IF($A40="","",N(M40)-N(N40)) | Q40: =IF($A40="","",IFERROR(SUMPRODUCT(('[1]عهد ومصروفات دمياط'!$H$8:$H$5007=$A40)*('[1]عهد ومصروفات دمياط'!$S$8:$S$5007=5)*'[1]عهد ومصروفات دمياط'!$T$8:$T$5007),0)) | R40: =IF($A40="","",N(P40)-N(Q40)) | T40: =IF($A40="","",IFERROR(SUMPRODUCT(('[1]عهد ومصروفات دمياط'!$H$8:$H$5007=$A40)*('[1]عهد ومصروفات دمياط'!$S$8:$S$5007=6)*'[1]عهد ومصروفات دمياط'!$T$8:$T$5007),0)) | U40: =IF($A40="","",N(S40)-N(T40)) | W40: =IF($A40="","",IFERROR(SUMPRODUCT(('[1]عهد ومصروفات دمياط'!$H$8:$H$5007=$A40)*('[1]عهد ومصروفات دمياط'!$S$8:$S$5007=7)*'[1]عهد ومصروفات دمياط'!$T$8:$T$5007),0)) | X40: =IF($A40="","",N(V40)-N(W40)) | Z40: =IF($A40="","",IFERROR(SUMPRODUCT(('[1]عهد ومصروفات دمياط'!$H$8:$H$5007=$A40)*('[1]عهد ومصروفات دمياط'!$S$8:$S$5007=8)*'[1]عهد ومصروفات دمياط'!$T$8:$T$5007),0)) | AA40: =IF($A40="","",N(Y40)-N(Z40)) | AC40: =IF($A40="","",IFERROR(SUMPRODUCT(('[1]عهد ومصروفات دمياط'!$H$8:$H$5007=$A40)*('[1]عهد ومصروفات دمياط'!$S$8:$S$5007=9)*'[1]عهد ومصروفات دمياط'!$T$8:$T$5007),0)) | AD40: =IF($A40="","",N(AB40)-N(AC40)) | AF40: =IF($A40="","",IFERROR(SUMPRODUCT(('[1]عهد ومصروفات دمياط'!$H$8:$H$5007=$A40)*('[1]عهد ومصروفات دمياط'!$S$8:$S$5007=10)*'[1]عهد ومصروفات دمياط'!$T$8:$T$5007),0)) | AG40: =IF($A40="","",N(AE40)-N(AF40)) | AI40: =IF($A40="","",IFERROR(SUMPRODUCT(('[1]عهد ومصروفات دمياط'!$H$8:$H$5007=$A40)*('[1]عهد ومصروفات دمياط'!$S$8:$S$5007=11)*'[1]عهد ومصروفات دمياط'!$T$8:$T$5007),0)) | AJ40: =IF($A40="","",N(AH40)-N(AI40)) | AL40: =IF($A40="","",IFERROR(SUMPRODUCT(('[1]عهد ومصروفات دمياط'!$H$8:$H$5007=$A40)*('[1]عهد ومصروفات دمياط'!$S$8:$S$5007=12)*'[1]عهد ومصروفات دمياط'!$T$8:$T$5007),0)) | AM40: =IF($A40="","",N(AK40)-N(AL40)) | AN40: =IF(A40="","",N(D40)+N(G40)+N(J40)+N(M40)+N(P40)+N(S40)+N(V40)+N(Y40)+N(AB40)+N(AE40)+N(AH40)+N(AK40)) | AO40: =IF(A40="","",N(E40)+N(H40)+N(K40)+N(N40)+N(Q40)+N(T40)+N(W40)+N(Z40)+N(AC40)+N(AF40)+N(AI40)+N(AL40)) | AP40: =IF(A40="","",N(B40)-AO40) | AQ40: =IF(A40="",0,(N(F40)<0)+(N(I40)<0)+(N(L40)<0)+(N(O40)<0)+(N(R40)<0)+(N(U40)<0)+(N(X40)<0)+(N(AA40)<0)+(N(AD40)<0)+(N(AG40)<0)+(N(AJ40)<0)+(N(AM40)<0)) | AR40: =IF(A40="",0,MAX(0,-N(F40))+MAX(0,-N(I40))+MAX(0,-N(L40))+MAX(0,-N(O40))+MAX(0,-N(R40))+MAX(0,-N(U40))+MAX(0,-N(X40))+MAX(0,-N(AA40))+MAX(0,-N(AD40))+MAX(0,-N(AG40))+MAX(0,-N(AJ40))+MAX(0,-N(AM40))) | AS40: =IF(A40="",0,IF(OR(N(AP40)<0,AQ40>0),1,0)) | AT40: =AT39+AS40 | AU40: =IF(A40="",-1,N(AO40)+ROW()/10000000)
C41: =IF(A41="","",N(B41)/12) | E41: =IF($A41="","",IFERROR(SUMPRODUCT(('[1]عهد ومصروفات دمياط'!$H$8:$H$5007=$A41)*('[1]عهد ومصروفات دمياط'!$S$8:$S$5007=1)*'[1]عهد ومصروفات دمياط'!$T$8:$T$5007),0)) | F41: =IF($A41="","",N(D41)-N(E41)) | H41: =IF($A41="","",IFERROR(SUMPRODUCT(('[1]عهد ومصروفات دمياط'!$H$8:$H$5007=$A41)*('[1]عهد ومصروفات دمياط'!$S$8:$S$5007=2)*'[1]عهد ومصروفات دمياط'!$T$8:$T$5007),0)) | I41: =IF($A41="","",N(G41)-N(H41)) | K41: =IF($A41="","",IFERROR(SUMPRODUCT(('[1]عهد ومصروفات دمياط'!$H$8:$H$5007=$A41)*('[1]عهد ومصروفات دمياط'!$S$8:$S$5007=3)*'[1]عهد ومصروفات دمياط'!$T$8:$T$5007),0)) | L41: =IF($A41="","",N(J41)-N(K41)) | N41: =IF($A41="","",IFERROR(SUMPRODUCT(('[1]عهد ومصروفات دمياط'!$H$8:$H$5007=$A41)*('[1]عهد ومصروفات دمياط'!$S$8:$S$5007=4)*'[1]عهد ومصروفات دمياط'!$T$8:$T$5007),0)) | O41: =IF($A41="","",N(M41)-N(N41)) | Q41: =IF($A41="","",IFERROR(SUMPRODUCT(('[1]عهد ومصروفات دمياط'!$H$8:$H$5007=$A41)*('[1]عهد ومصروفات دمياط'!$S$8:$S$5007=5)*'[1]عهد ومصروفات دمياط'!$T$8:$T$5007),0)) | R41: =IF($A41="","",N(P41)-N(Q41)) | T41: =IF($A41="","",IFERROR(SUMPRODUCT(('[1]عهد ومصروفات دمياط'!$H$8:$H$5007=$A41)*('[1]عهد ومصروفات دمياط'!$S$8:$S$5007=6)*'[1]عهد ومصروفات دمياط'!$T$8:$T$5007),0)) | U41: =IF($A41="","",N(S41)-N(T41)) | W41: =IF($A41="","",IFERROR(SUMPRODUCT(('[1]عهد ومصروفات دمياط'!$H$8:$H$5007=$A41)*('[1]عهد ومصروفات دمياط'!$S$8:$S$5007=7)*'[1]عهد ومصروفات دمياط'!$T$8:$T$5007),0)) | X41: =IF($A41="","",N(V41)-N(W41)) | Z41: =IF($A41="","",IFERROR(SUMPRODUCT(('[1]عهد ومصروفات دمياط'!$H$8:$H$5007=$A41)*('[1]عهد ومصروفات دمياط'!$S$8:$S$5007=8)*'[1]عهد ومصروفات دمياط'!$T$8:$T$5007),0)) | AA41: =IF($A41="","",N(Y41)-N(Z41)) | AC41: =IF($A41="","",IFERROR(SUMPRODUCT(('[1]عهد ومصروفات دمياط'!$H$8:$H$5007=$A41)*('[1]عهد ومصروفات دمياط'!$S$8:$S$5007=9)*'[1]عهد ومصروفات دمياط'!$T$8:$T$5007),0)) | AD41: =IF($A41="","",N(AB41)-N(AC41)) | AF41: =IF($A41="","",IFERROR(SUMPRODUCT(('[1]عهد ومصروفات دمياط'!$H$8:$H$5007=$A41)*('[1]عهد ومصروفات دمياط'!$S$8:$S$5007=10)*'[1]عهد ومصروفات دمياط'!$T$8:$T$5007),0)) | AG41: =IF($A41="","",N(AE41)-N(AF41)) | AI41: =IF($A41="","",IFERROR(SUMPRODUCT(('[1]عهد ومصروفات دمياط'!$H$8:$H$5007=$A41)*('[1]عهد ومصروفات دمياط'!$S$8:$S$5007=11)*'[1]عهد ومصروفات دمياط'!$T$8:$T$5007),0)) | AJ41: =IF($A41="","",N(AH41)-N(AI41)) | AL41: =IF($A41="","",IFERROR(SUMPRODUCT(('[1]عهد ومصروفات دمياط'!$H$8:$H$5007=$A41)*('[1]عهد ومصروفات دمياط'!$S$8:$S$5007=12)*'[1]عهد ومصروفات دمياط'!$T$8:$T$5007),0)) | AM41: =IF($A41="","",N(AK41)-N(AL41)) | AN41: =IF(A41="","",N(D41)+N(G41)+N(J41)+N(M41)+N(P41)+N(S41)+N(V41)+N(Y41)+N(AB41)+N(AE41)+N(AH41)+N(AK41)) | AO41: =IF(A41="","",N(E41)+N(H41)+N(K41)+N(N41)+N(Q41)+N(T41)+N(W41)+N(Z41)+N(AC41)+N(AF41)+N(AI41)+N(AL41)) | AP41: =IF(A41="","",N(B41)-AO41) | AQ41: =IF(A41="",0,(N(F41)<0)+(N(I41)<0)+(N(L41)<0)+(N(O41)<0)+(N(R41)<0)+(N(U41)<0)+(N(X41)<0)+(N(AA41)<0)+(N(AD41)<0)+(N(AG41)<0)+(N(AJ41)<0)+(N(AM41)<0)) | AR41: =IF(A41="",0,MAX(0,-N(F41))+MAX(0,-N(I41))+MAX(0,-N(L41))+MAX(0,-N(O41))+MAX(0,-N(R41))+MAX(0,-N(U41))+MAX(0,-N(X41))+MAX(0,-N(AA41))+MAX(0,-N(AD41))+MAX(0,-N(AG41))+MAX(0,-N(AJ41))+MAX(0,-N(AM41))) | AS41: =IF(A41="",0,IF(OR(N(AP41)<0,AQ41>0),1,0)) | AT41: =AT40+AS41 | AU41: =IF(A41="",-1,N(AO41)+ROW()/10000000)
C42: =IF(A42="","",N(B42)/12) | E42: =IF($A42="","",IFERROR(SUMPRODUCT(('[1]عهد ومصروفات دمياط'!$H$8:$H$5007=$A42)*('[1]عهد ومصروفات دمياط'!$S$8:$S$5007=1)*'[1]عهد ومصروفات دمياط'!$T$8:$T$5007),0)) | F42: =IF($A42="","",N(D42)-N(E42)) | H42: =IF($A42="","",IFERROR(SUMPRODUCT(('[1]عهد ومصروفات دمياط'!$H$8:$H$5007=$A42)*('[1]عهد ومصروفات دمياط'!$S$8:$S$5007=2)*'[1]عهد ومصروفات دمياط'!$T$8:$T$5007),0)) | I42: =IF($A42="","",N(G42)-N(H42)) | K42: =IF($A42="","",IFERROR(SUMPRODUCT(('[1]عهد ومصروفات دمياط'!$H$8:$H$5007=$A42)*('[1]عهد ومصروفات دمياط'!$S$8:$S$5007=3)*'[1]عهد ومصروفات دمياط'!$T$8:$T$5007),0)) | L42: =IF($A42="","",N(J42)-N(K42)) | N42: =IF($A42="","",IFERROR(SUMPRODUCT(('[1]عهد ومصروفات دمياط'!$H$8:$H$5007=$A42)*('[1]عهد ومصروفات دمياط'!$S$8:$S$5007=4)*'[1]عهد ومصروفات دمياط'!$T$8:$T$5007),0)) | O42: =IF($A42="","",N(M42)-N(N42)) | Q42: =IF($A42="","",IFERROR(SUMPRODUCT(('[1]عهد ومصروفات دمياط'!$H$8:$H$5007=$A42)*('[1]عهد ومصروفات دمياط'!$S$8:$S$5007=5)*'[1]عهد ومصروفات دمياط'!$T$8:$T$5007),0)) | R42: =IF($A42="","",N(P42)-N(Q42)) | T42: =IF($A42="","",IFERROR(SUMPRODUCT(('[1]عهد ومصروفات دمياط'!$H$8:$H$5007=$A42)*('[1]عهد ومصروفات دمياط'!$S$8:$S$5007=6)*'[1]عهد ومصروفات دمياط'!$T$8:$T$5007),0)) | U42: =IF($A42="","",N(S42)-N(T42)) | W42: =IF($A42="","",IFERROR(SUMPRODUCT(('[1]عهد ومصروفات دمياط'!$H$8:$H$5007=$A42)*('[1]عهد ومصروفات دمياط'!$S$8:$S$5007=7)*'[1]عهد ومصروفات دمياط'!$T$8:$T$5007),0)) | X42: =IF($A42="","",N(V42)-N(W42)) | Z42: =IF($A42="","",IFERROR(SUMPRODUCT(('[1]عهد ومصروفات دمياط'!$H$8:$H$5007=$A42)*('[1]عهد ومصروفات دمياط'!$S$8:$S$5007=8)*'[1]عهد ومصروفات دمياط'!$T$8:$T$5007),0)) | AA42: =IF($A42="","",N(Y42)-N(Z42)) | AC42: =IF($A42="","",IFERROR(SUMPRODUCT(('[1]عهد ومصروفات دمياط'!$H$8:$H$5007=$A42)*('[1]عهد ومصروفات دمياط'!$S$8:$S$5007=9)*'[1]عهد ومصروفات دمياط'!$T$8:$T$5007),0)) | AD42: =IF($A42="","",N(AB42)-N(AC42)) | AF42: =IF($A42="","",IFERROR(SUMPRODUCT(('[1]عهد ومصروفات دمياط'!$H$8:$H$5007=$A42)*('[1]عهد ومصروفات دمياط'!$S$8:$S$5007=10)*'[1]عهد ومصروفات دمياط'!$T$8:$T$5007),0)) | AG42: =IF($A42="","",N(AE42)-N(AF42)) | AI42: =IF($A42="","",IFERROR(SUMPRODUCT(('[1]عهد ومصروفات دمياط'!$H$8:$H$5007=$A42)*('[1]عهد ومصروفات دمياط'!$S$8:$S$5007=11)*'[1]عهد ومصروفات دمياط'!$T$8:$T$5007),0)) | AJ42: =IF($A42="","",N(AH42)-N(AI42)) | AL42: =IF($A42="","",IFERROR(SUMPRODUCT(('[1]عهد ومصروفات دمياط'!$H$8:$H$5007=$A42)*('[1]عهد ومصروفات دمياط'!$S$8:$S$5007=12)*'[1]عهد ومصروفات دمياط'!$T$8:$T$5007),0)) | AM42: =IF($A42="","",N(AK42)-N(AL42)) | AN42: =IF(A42="","",N(D42)+N(G42)+N(J42)+N(M42)+N(P42)+N(S42)+N(V42)+N(Y42)+N(AB42)+N(AE42)+N(AH42)+N(AK42)) | AO42: =IF(A42="","",N(E42)+N(H42)+N(K42)+N(N42)+N(Q42)+N(T42)+N(W42)+N(Z42)+N(AC42)+N(AF42)+N(AI42)+N(AL42)) | AP42: =IF(A42="","",N(B42)-AO42) | AQ42: =IF(A42="",0,(N(F42)<0)+(N(I42)<0)+(N(L42)<0)+(N(O42)<0)+(N(R42)<0)+(N(U42)<0)+(N(X42)<0)+(N(AA42)<0)+(N(AD42)<0)+(N(AG42)<0)+(N(AJ42)<0)+(N(AM42)<0)) | AR42: =IF(A42="",0,MAX(0,-N(F42))+MAX(0,-N(I42))+MAX(0,-N(L42))+MAX(0,-N(O42))+MAX(0,-N(R42))+MAX(0,-N(U42))+MAX(0,-N(X42))+MAX(0,-N(AA42))+MAX(0,-N(AD42))+MAX(0,-N(AG42))+MAX(0,-N(AJ42))+MAX(0,-N(AM42))) | AS42: =IF(A42="",0,IF(OR(N(AP42)<0,AQ42>0),1,0)) | AT42: =AT41+AS42 | AU42: =IF(A42="",-1,N(AO42)+ROW()/10000000)
